<sdf version='1.6'>
  <model name='MRC_"Plastun"'>
    <link name='chassis'>
      <pose frame=''>0 0 0 0 -0 0</pose>
      <inertial>
        <pose frame=''>0.318453 -0.004734 0.074568 0 -0 0</pose>
        <mass>31.0001</mass>
        <inertia>
          <ixx>0.463915</ixx>
          <ixy>-0.000471007</ixy>
          <ixz>0.0219991</ixz>
          <iyy>0.467563</iyy>
          <iyz>0.00280295</iyz>
          <izz>0.337105</izz>
        </inertia>
      </inertial>
      <collision name='chassis_collision'>
        <pose frame=''>0.32045 0 0.06272 0 -0 0</pose>
        <geometry>
          <mesh>
            <scale>1 1 1</scale>
            <uri>model://plastun_description/meshes/STL_min/chassis.stl</uri>
          </mesh>
        </geometry>
        <surface>
          <contact>
            <ode/>
          </contact>
          <friction>
            <ode/>
          </friction>
        </surface>
      </collision>
      <collision name='chassis_fixed_joint_lump__hokuyo_collision_1'>
        <pose frame=''>0.15582 0.0808 0.47783 0 -0 0</pose>
        <geometry>
          <box>
            <size>0.06524 0.079833 0.102579</size>
          </box>
        </geometry>
        <surface>
          <contact>
            <ode/>
          </contact>
          <friction>
            <ode/>
          </friction>
        </surface>
      </collision>
      <collision name='chassis_fixed_joint_lump__turrel_vniz_collision_2'>
        <pose frame=''>0.25857 -0.01238 0.42994 0 -0 0</pose>
        <geometry>
          <mesh>
            <scale>1 1 1</scale>
            <uri>model://plastun_description/meshes/STL_min/turrel_vniz.stl</uri>
          </mesh>
        </geometry>
        <surface>
          <contact>
            <ode/>
          </contact>
          <friction>
            <ode/>
          </friction>
        </surface>
      </collision>
      <visual name='chassis_visual'>
        <pose frame=''>0.32045 0 0.06272 0 -0 0</pose>
        <geometry>
          <mesh>
            <scale>1 1 1</scale>
            <uri>model://plastun_description/meshes/STL_min/chassis.stl</uri>
          </mesh>
        </geometry>
        <material>
          <script>
            <name>Gazebo/Grey</name>
            <uri>file://media/materials/scripts/gazebo.material</uri>
          </script>
        </material>
      </visual>
      <visual name='chassis_fixed_joint_lump__hokuyo_visual_1'>
        <pose frame=''>0.15582 0.0808 0.42783 0 -0 0</pose>
        <geometry>
          <mesh>
            <scale>1 1 1</scale>
            <uri>model://plastun_description/meshes/STL_min/hokuyo.stl</uri>
          </mesh>
        </geometry>
        <material>
          <script>
            <name>Gazebo/Grey</name>
            <uri>file://media/materials/scripts/gazebo.material</uri>
          </script>
        </material>
      </visual>
      <visual name='chassis_fixed_joint_lump__turrel_vniz_visual_2'>
        <pose frame=''>0.25857 -0.01238 0.42994 0 -0 0</pose>
        <geometry>
          <mesh>
            <scale>1 1 1</scale>
            <uri>model://plastun_description/meshes/STL_min/turrel_vniz.stl</uri>
          </mesh>
        </geometry>
        <material>
          <script>
            <name>Gazebo/Grey</name>
            <uri>file://media/materials/scripts/gazebo.material</uri>
          </script>
        </material>
      </visual>
      <velocity_decay/>
      <velocity_decay/>
      <velocity_decay/>
      <sensor name='head_hokuyo_sensor' type='gpu_ray'>
        <visualize>1</visualize>
        <update_rate>40</update_rate>
        <ray>
          <scan>
            <horizontal>
              <samples>720</samples>
              <resolution>1</resolution>
              <min_angle>-1.4708</min_angle>
              <max_angle>1.4708</max_angle>
            </horizontal>
          </scan>
          <range>
            <min>0.1</min>
            <max>30</max>
            <resolution>0.01</resolution>
          </range>
          <noise>
            <type>gaussian</type>
            <mean>0</mean>
            <stddev>0.01</stddev>
          </noise>
        </ray>
        <plugin name='gazebo_ros_head_hokuyo_controller' filename='libgazebo_ros_gpu_laser.so'>
          <topicName>plastun/laser/scan</topicName>
          <frameName>hokuyo_link</frameName>
        </plugin>
        <pose frame=''>0.15582 0.0808 2 0 -0 3.14</pose>
      </sensor>
      <gravity>1</gravity>
      <velocity_decay/>
      <self_collide>0</self_collide>
    </link>
    <link name='turrel_sered'>
      <pose frame=''>0.25902 -0.01271 0.56468 0 -0 0</pose>
      <inertial>
        <pose frame=''>0 0 0 0 -0 0</pose>
        <mass>1</mass>
        <inertia>
          <ixx>0.166667</ixx>
          <ixy>0</ixy>
          <ixz>0</ixz>
          <iyy>0.166667</iyy>
          <iyz>0</iyz>
          <izz>0.166667</izz>
        </inertia>
      </inertial>
      <collision name='turrel_sered_collision'>
        <pose frame=''>0 0 0 0 -0 0</pose>
        <geometry>
          <mesh>
            <scale>1 1 1</scale>
            <uri>model://plastun_description/meshes/STL_min/turrel_sered.stl</uri>
          </mesh>
        </geometry>
        <surface>
          <contact>
            <ode/>
          </contact>
          <friction>
            <ode/>
          </friction>
        </surface>
      </collision>
      <visual name='turrel_sered_visual'>
        <pose frame=''>0 0 0 0 -0 0</pose>
        <geometry>
          <mesh>
            <scale>1 1 1</scale>
            <uri>model://plastun_description/meshes/STL_min/turrel_sered.stl</uri>
          </mesh>
        </geometry>
        <material>
          <script>
            <name>Gazebo/Grey</name>
            <uri>file://media/materials/scripts/gazebo.material</uri>
          </script>
        </material>
      </visual>
      <gravity>1</gravity>
      <velocity_decay/>
      <self_collide>0</self_collide>
    </link>
    <joint name='turrel_vniz _ turrel_sered revolute' type='revolute'>
      <child>turrel_sered</child>
      <parent>chassis</parent>
      <axis>
        <xyz>0 0 1</xyz>
        <limit>
          <lower>-5</lower>
          <upper>5</upper>
          <effort>2</effort>
          <velocity>100</velocity>
        </limit>
        <dynamics>
          <spring_reference>0</spring_reference>
          <spring_stiffness>0</spring_stiffness>
        </dynamics>
        <use_parent_model_frame>1</use_parent_model_frame>
      </axis>
    </joint>
    <link name='turrel_vverh'>
      <pose frame=''>0.26208 -0.00803 0.69346 0 -0 0</pose>
      <inertial>
        <pose frame=''>-0.040349 -0.072867 0.028583 0 -0 0</pose>
        <mass>1.52996</mass>
        <inertia>
          <ixx>0.351851</ixx>
          <ixy>-0.00850413</ixy>
          <ixz>0.0034716</ixz>
          <iyy>0.343208</iyy>
          <iyz>0.00604847</iyz>
          <izz>0.356349</izz>
        </inertia>
      </inertial>
      <collision name='turrel_vverh_collision'>
        <pose frame=''>0 0 0 0 -0 0</pose>
        <geometry>
          <mesh>
            <scale>1 1 1</scale>
            <uri>model://plastun_description/meshes/STL_min/turrel_vverh.stl</uri>
          </mesh>
        </geometry>
        <surface>
          <contact>
            <ode/>
          </contact>
          <friction>
            <ode/>
          </friction>
        </surface>
      </collision>
      <collision name='turrel_vverh_fixed_joint_lump__camera_1_collision_1'>
        <pose frame=''>-0.07152 -0.21215 -0.017 0 -0 0</pose>
        <geometry>
          <mesh>
            <scale>1 1 1</scale>
            <uri>model://plastun_description/meshes/STL_min/camera.stl</uri>
          </mesh>
        </geometry>
        <surface>
          <contact>
            <ode/>
          </contact>
          <friction>
            <ode/>
          </friction>
        </surface>
      </collision>
      <collision name='turrel_vverh_fixed_joint_lump__lazer_ukazka_collision_2'>
        <pose frame=''>-0.11918 -0.21104 0.08848 0 -0 0</pose>
        <geometry>
          <mesh>
            <scale>1 1 1</scale>
            <uri>model://plastun_description/meshes/STL_min/lazer_ukazka.stl</uri>
          </mesh>
        </geometry>
        <surface>
          <contact>
            <ode/>
          </contact>
          <friction>
            <ode/>
          </friction>
        </surface>
      </collision>
      <collision name='turrel_vverh_fixed_joint_lump__camera_2_collision_3'>
        <pose frame=''>-0.07152 0.21176 -0.017 0 -0 0</pose>
        <geometry>
          <mesh>
            <scale>1 1 1</scale>
            <uri>model://plastun_description/meshes/STL_min/camera.stl</uri>
          </mesh>
        </geometry>
        <surface>
          <contact>
            <ode/>
          </contact>
          <friction>
            <ode/>
          </friction>
        </surface>
      </collision>
      <visual name='turrel_vverh_visual'>
        <pose frame=''>0 0 0 0 -0 0</pose>
        <geometry>
          <mesh>
            <scale>1 1 1</scale>
            <uri>model://plastun_description/meshes/STL_min/turrel_vverh.stl</uri>
          </mesh>
        </geometry>
        <material>
          <script>
            <name>Gazebo/Grey</name>
            <uri>file://media/materials/scripts/gazebo.material</uri>
          </script>
        </material>
      </visual>
      <visual name='turrel_vverh_fixed_joint_lump__camera_1_visual_1'>
        <pose frame=''>-0.07152 -0.21215 -0.017 0 -0 0</pose>
        <geometry>
          <mesh>
            <scale>1 1 1</scale>
            <uri>model://plastun_description/meshes/STL_min/camera.stl</uri>
          </mesh>
        </geometry>
        <material>
          <script>
            <name>Gazebo/Grey</name>
            <uri>file://media/materials/scripts/gazebo.material</uri>
          </script>
        </material>
      </visual>
      <visual name='turrel_vverh_fixed_joint_lump__lazer_ukazka_visual_2'>
        <pose frame=''>-0.11918 -0.21104 0.08848 0 -0 0</pose>
        <geometry>
          <mesh>
            <scale>1 1 1</scale>
            <uri>model://plastun_description/meshes/STL_min/lazer_ukazka.stl</uri>
          </mesh>
        </geometry>
        <material>
          <script>
            <uri>__default__</uri>
            <name>__default__</name>
          </script>
        </material>
      </visual>
      <visual name='turrel_vverh_fixed_joint_lump__camera_2_visual_3'>
        <pose frame=''>-0.07152 0.21176 -0.017 0 -0 0</pose>
        <geometry>
          <mesh>
            <scale>1 1 1</scale>
            <uri>model://plastun_description/meshes/STL_min/camera.stl</uri>
          </mesh>
        </geometry>
        <material>
          <script>
            <name>Gazebo/Grey</name>
            <uri>file://media/materials/scripts/gazebo.material</uri>
          </script>
        </material>
      </visual>
      <velocity_decay/>
      <velocity_decay/>
      <velocity_decay/>
      <sensor name='camera' type='camera'>
        <camera name='__default__'>
          <horizontal_fov>1.0123</horizontal_fov>
          <image>
            <width>320</width>
            <height>200</height>
          </image>
          <clip>
            <near>0.001</near>
            <far>100</far>
          </clip>
        </camera>
        <always_on>1</always_on>
        <update_rate>30</update_rate>
        <visualize>1</visualize>
        <plugin name='camera_controller' filename='libgazebo_ros_camera.so'>
          <alwaysOn>true</alwaysOn>
          <updateRate>30</updateRate>
          <cameraName>plastun/camera_1</cameraName>
          <imageTopicName>image_raw_1</imageTopicName>
          <cameraInfoTopicName>camera_info_1</cameraInfoTopicName>
          <frameName>camera_link</frameName>
          <hackBaseline>0.07</hackBaseline>
          <distortionK1>0.0</distortionK1>
          <distortionK2>0.0</distortionK2>
          <distortionK3>0.0</distortionK3>
          <distortionT1>0.0</distortionT1>
          <distortionT2>0.0</distortionT2>
        </plugin>
        <pose frame=''>-0.07152 -0.21215 -0.017 0 -0 0</pose>
      </sensor>
      <velocity_decay/>
      <sensor name='head_hokuyo_sensor' type='gpu_ray'>
        <visualize>1</visualize>
        <update_rate>40</update_rate>
        <ray>
          <scan>
            <horizontal>
              <samples>2</samples>
              <resolution>1</resolution>
              <min_angle>-0.005</min_angle>
              <max_angle>0.005</max_angle>
            </horizontal>
          </scan>
          <range>
            <min>0.1</min>
            <max>30</max>
            <resolution>0.01</resolution>
          </range>
          <noise>
            <type>gaussian</type>
            <mean>0</mean>
            <stddev>0.01</stddev>
          </noise>
        </ray>
        <plugin name='gazebo_ros_head_hokuyo_controller' filename='libgazebo_ros_gpu_laser.so'>
          <topicName>plastun/laser/scan_ukaz</topicName>
          <frameName>ukaz_link</frameName>
        </plugin>
        <pose frame=''>-0.11918 -0.21104 0.08848 0 -0 0</pose>
      </sensor>
      <velocity_decay/>
      <gravity>1</gravity>
      <velocity_decay/>
      <self_collide>0</self_collide>
      <sensor name='camera' type='camera'>
        <camera name='__default__'>
          <horizontal_fov>1.0123</horizontal_fov>
          <image>
            <width>320</width>
            <height>200</height>
          </image>
          <clip>
            <near>0.001</near>
            <far>100</far>
          </clip>
        </camera>
        <always_on>1</always_on>
        <update_rate>30</update_rate>
        <visualize>1</visualize>
        <plugin name='camera_controller' filename='libgazebo_ros_camera.so'>
          <alwaysOn>true</alwaysOn>
          <updateRate>30</updateRate>
          <cameraName>plastun/camera_2</cameraName>
          <imageTopicName>image_raw_2</imageTopicName>
          <cameraInfoTopicName>camera_info_2</cameraInfoTopicName>
          <frameName>camera_link</frameName>
          <hackBaseline>0.07</hackBaseline>
          <distortionK1>0.0</distortionK1>
          <distortionK2>0.0</distortionK2>
          <distortionK3>0.0</distortionK3>
          <distortionT1>0.0</distortionT1>
          <distortionT2>0.0</distortionT2>
        </plugin>
        <pose frame=''>-0.07152 0.21176 -0.017 0 -0 0</pose>
      </sensor>
    </link>
    <joint name='turrel_sered _ turrel_vverh up-to-down' type='revolute'>
      <child>turrel_vverh</child>
      <parent>turrel_sered</parent>
      <axis>
        <xyz>0 1 0</xyz>
        <limit>
          <lower>-1</lower>
          <upper>1</upper>
          <effort>1</effort>
          <velocity>100</velocity>
        </limit>
        <dynamics>
          <spring_reference>0</spring_reference>
          <spring_stiffness>0</spring_stiffness>
        </dynamics>
        <use_parent_model_frame>1</use_parent_model_frame>
      </axis>
    </joint>
    <link name='wheel_left_1'>
      <pose frame=''>0.36566 -0.20499 0.15237 0 -0 0</pose>
      <inertial>
        <pose frame=''>0 0 0 0 -0 0</pose>
        <mass>1</mass>
        <inertia>
          <ixx>0.166667</ixx>
          <ixy>0</ixy>
          <ixz>0</ixz>
          <iyy>0.166667</iyy>
          <iyz>0</iyz>
          <izz>0.166667</izz>
        </inertia>
      </inertial>
      <collision name='wheel_left_1_collision'>
        <pose frame=''>0 0 0 1.5708 -0 0</pose>
        <geometry>
          <cylinder>
            <length>0.09</length>
            <radius>0.096</radius>
          </cylinder>
        </geometry>
      </collision>
      <visual name='wheel_left_1_visual'>
        <pose frame=''>0 0 0 0 -0 0</pose>
        <geometry>
          <mesh>
            <scale>1 1 1</scale>
            <uri>model://plastun_description/meshes/STL_min/wheel.stl</uri>
          </mesh>
        </geometry>
      </visual>
    </link>
    <joint name='wheel_lev_1' type='revolute'>
      <child>wheel_left_1</child>
      <parent>chassis</parent>
      <axis>
        <xyz>0 -1 0</xyz>
        <limit>
          <lower>-1e+50</lower>
          <upper>1e+50</upper>
          <effort>-1</effort>
          <velocity>100</velocity>
        </limit>
        <dynamics>
          <spring_reference>0</spring_reference>
          <spring_stiffness>0</spring_stiffness>
        </dynamics>
        <use_parent_model_frame>1</use_parent_model_frame>
      </axis>
    </joint>
    <link name='wheel_left_2'>
      <pose frame=''>0.13874 -0.20499 0.15237 0 -0 0</pose>
      <inertial>
        <pose frame=''>0 0 0 0 -0 0</pose>
        <mass>1</mass>
        <inertia>
          <ixx>0.166667</ixx>
          <ixy>0</ixy>
          <ixz>0</ixz>
          <iyy>0.166667</iyy>
          <iyz>0</iyz>
          <izz>0.166667</izz>
        </inertia>
      </inertial>
      <collision name='wheel_left_2_collision'>
        <pose frame=''>0 0 0 1.5708 -0 0</pose>
        <geometry>
          <cylinder>
            <length>0.09</length>
            <radius>0.096</radius>
          </cylinder>
        </geometry>
      </collision>
      <visual name='wheel_left_2_visual'>
        <pose frame=''>0 0 0 0 -0 0</pose>
        <geometry>
          <mesh>
            <scale>1 1 1</scale>
            <uri>model://plastun_description/meshes/STL_min/wheel.stl</uri>
          </mesh>
        </geometry>
      </visual>
    </link>
    <joint name='wheel_lev_2' type='revolute'>
      <child>wheel_left_2</child>
      <parent>chassis</parent>
      <axis>
        <xyz>0 -1 0</xyz>
        <limit>
          <lower>-1e+50</lower>
          <upper>1e+50</upper>
          <effort>-1</effort>
          <velocity>100</velocity>
        </limit>
        <dynamics>
          <spring_reference>0</spring_reference>
          <spring_stiffness>0</spring_stiffness>
        </dynamics>
        <use_parent_model_frame>1</use_parent_model_frame>
      </axis>
    </joint>
    <link name='wheel_left_3'>
      <pose frame=''>0.58393 -0.20499 0.15237 0 -0 0</pose>
      <inertial>
        <pose frame=''>0 0 0 0 -0 0</pose>
        <mass>1</mass>
        <inertia>
          <ixx>0.166667</ixx>
          <ixy>0</ixy>
          <ixz>0</ixz>
          <iyy>0.166667</iyy>
          <iyz>0</iyz>
          <izz>0.166667</izz>
        </inertia>
      </inertial>
      <collision name='wheel_left_3_collision'>
        <pose frame=''>0 0 0 1.5708 -0 0</pose>
        <geometry>
          <cylinder>
            <length>0.09</length>
            <radius>0.096</radius>
          </cylinder>
        </geometry>
      </collision>
      <visual name='wheel_left_3_visual'>
        <pose frame=''>0 0 0 0 -0 0</pose>
        <geometry>
          <mesh>
            <scale>1 1 1</scale>
            <uri>model://plastun_description/meshes/STL_min/wheel.stl</uri>
          </mesh>
        </geometry>
      </visual>
    </link>
    <joint name='wheel_lev_3' type='revolute'>
      <child>wheel_left_3</child>
      <parent>chassis</parent>
      <axis>
        <xyz>0 -1 0</xyz>
        <limit>
          <lower>-1e+50</lower>
          <upper>1e+50</upper>
          <effort>-1</effort>
          <velocity>100</velocity>
        </limit>
        <dynamics>
          <spring_reference>0</spring_reference>
          <spring_stiffness>0</spring_stiffness>
        </dynamics>
        <use_parent_model_frame>1</use_parent_model_frame>
      </axis>
    </joint>
    <link name='wheel_right_1'>
      <pose frame=''>0.13874 0.20499 0.15237 0 -0 0</pose>
      <inertial>
        <pose frame=''>0 0 0 0 -0 0</pose>
        <mass>1</mass>
        <inertia>
          <ixx>0.166667</ixx>
          <ixy>0</ixy>
          <ixz>0</ixz>
          <iyy>0.166667</iyy>
          <iyz>0</iyz>
          <izz>0.166667</izz>
        </inertia>
      </inertial>
      <collision name='wheel_right_1_collision'>
        <pose frame=''>0 0 0 1.5708 -0 0</pose>
        <geometry>
          <cylinder>
            <length>0.09</length>
            <radius>0.096</radius>
          </cylinder>
        </geometry>
      </collision>
      <visual name='wheel_right_1_visual'>
        <pose frame=''>0 0 0 0 -0 0</pose>
        <geometry>
          <mesh>
            <scale>1 1 1</scale>
            <uri>model://plastun_description/meshes/STL_min/wheel.stl</uri>
          </mesh>
        </geometry>
      </visual>
    </link>
    <joint name='wheel_prav_1' type='revolute'>
      <child>wheel_right_1</child>
      <parent>chassis</parent>
      <axis>
        <xyz>0 -1 0</xyz>
        <limit>
          <lower>-1e+50</lower>
          <upper>1e+50</upper>
          <effort>-1</effort>
          <velocity>100</velocity>
        </limit>
        <dynamics>
          <spring_reference>0</spring_reference>
          <spring_stiffness>0</spring_stiffness>
        </dynamics>
        <use_parent_model_frame>1</use_parent_model_frame>
      </axis>
    </joint>
    <link name='wheel_right_2'>
      <pose frame=''>0.36566 0.20499 0.15237 0 -0 0</pose>
      <inertial>
        <pose frame=''>0 0 0 0 -0 0</pose>
        <mass>1</mass>
        <inertia>
          <ixx>0.166667</ixx>
          <ixy>0</ixy>
          <ixz>0</ixz>
          <iyy>0.166667</iyy>
          <iyz>0</iyz>
          <izz>0.166667</izz>
        </inertia>
      </inertial>
      <collision name='wheel_right_2_collision'>
        <pose frame=''>0 0 0 1.5708 -0 0</pose>
        <geometry>
          <cylinder>
            <length>0.09</length>
            <radius>0.096</radius>
          </cylinder>
        </geometry>
      </collision>
      <visual name='wheel_right_2_visual'>
        <pose frame=''>0 0 0 0 -0 0</pose>
        <geometry>
          <mesh>
            <scale>1 1 1</scale>
            <uri>model://plastun_description/meshes/STL_min/wheel.stl</uri>
          </mesh>
        </geometry>
      </visual>
    </link>
    <joint name='wheel_prav_2' type='revolute'>
      <child>wheel_right_2</child>
      <parent>chassis</parent>
      <axis>
        <xyz>0 -1 0</xyz>
        <limit>
          <lower>-1e+50</lower>
          <upper>1e+50</upper>
          <effort>-1</effort>
          <velocity>100</velocity>
        </limit>
        <dynamics>
          <spring_reference>0</spring_reference>
          <spring_stiffness>0</spring_stiffness>
        </dynamics>
        <use_parent_model_frame>1</use_parent_model_frame>
      </axis>
    </joint>
    <link name='wheel_right_3'>
      <pose frame=''>0.58393 0.20499 0.15237 0 -0 0</pose>
      <inertial>
        <pose frame=''>0 0 0 0 -0 0</pose>
        <mass>1</mass>
        <inertia>
          <ixx>0.166667</ixx>
          <ixy>0</ixy>
          <ixz>0</ixz>
          <iyy>0.166667</iyy>
          <iyz>0</iyz>
          <izz>0.166667</izz>
        </inertia>
      </inertial>
      <collision name='wheel_right_3_collision'>
        <pose frame=''>0 0 0 1.5708 -0 0</pose>
        <geometry>
          <cylinder>
            <length>0.09</length>
            <radius>0.096</radius>
          </cylinder>
        </geometry>
      </collision>
      <visual name='wheel_right_3_visual'>
        <pose frame=''>0 0 0 0 -0 0</pose>
        <geometry>
          <mesh>
            <scale>1 1 1</scale>
            <uri>model://plastun_description/meshes/STL_min/wheel.stl</uri>
          </mesh>
        </geometry>
      </visual>
    </link>
    <joint name='wheel_prav_3' type='revolute'>
      <child>wheel_right_3</child>
      <parent>chassis</parent>
      <axis>
        <xyz>0 -1 0</xyz>
        <limit>
          <lower>-1e+50</lower>
          <upper>1e+50</upper>
          <effort>-1</effort>
          <velocity>100</velocity>
        </limit>
        <dynamics>
          <spring_reference>0</spring_reference>
          <spring_stiffness>0</spring_stiffness>
        </dynamics>
        <use_parent_model_frame>1</use_parent_model_frame>
      </axis>
    </joint>
    <plugin name='gazebo_ros_control' filename='libgazebo_ros_control.so'>
      <robotNamespace>/plastun</robotNamespace>
    </plugin>
    <static>0</static>
    <plugin name='skid_steer_drive_controller' filename='libgazebo_ros_skid_steer_drive.so'>
      <updateRate>100.0</updateRate>
      <robotNamespace>plastun</robotNamespace>
      <leftFrontJoint>wheel_lev_1</leftFrontJoint>
      <rightFrontJoint>wheel_prav_1</rightFrontJoint>
      <leftRearJoint>wheel_lev_3</leftRearJoint>
      <rightRearJoint>wheel_prav_3</rightRearJoint>
      <wheelSeparation>0.4</wheelSeparation>
      <wheelDiameter>0.192</wheelDiameter>
      <robotBaseFrame>chassis</robotBaseFrame>
      <torque>20</torque>
      <commandTopic>cmd_vel</commandTopic>
      <odometryTopic>odom</odometryTopic>
      <broadcastTF>false</broadcastTF>
    </plugin>
  </model>
</sdf>
