<?xml version="1.0"?>
<robot name="MRC_Plastun" xmlns:xacro="http://www.ros.org/wiki/xacro">

	<!-- Import all Gazebo-customization elements, including Gazebo colors -->
	<xacro:include filename="$(find plastun_description)/urdf/plastun.gazebo" />
	<!-- Import Rviz colors -->
	<xacro:include filename="$(find rrbot_description)/urdf/materials.xacro" />


	<!-- Constants for robot dimensions -->
	<xacro:property name="mass_wheels" value="1" />
	<xacro:property name="y_wheel" value="0.20499" />
	<xacro:property name="z_wheel" value=" 0.0925" />
	<xacro:property name="between_wheels" value="0.2213343" />

	<xacro:property name="x_camera" value="-0.07152" />
	<xacro:property name="y_camera" value="0.21176" />
	<xacro:property name="z_camera" value="0" />


	<xacro:macro name="wheel" params="prefix num side rev">
		<link name="wheel_${prefix}_${num}">
			<inertial>
				<mass value="${mass_wheels}"/>
				<origin rpy="0  0  0" xyz="0  0.000008  0"/>
				<inertia ixx="0.166667" ixy="0" ixz="0" iyy="0.166667" iyz="0" izz="0.166667"/>
			</inertial>
			<collision >
				<origin rpy="1.5708  0      0" xyz="0  0  0"/>
				<geometry>
					<cylinder length="0.09" radius="0.096"/>
				</geometry>
			</collision>
			<visual>
				<origin rpy="0  0  0" xyz="0  0  0"/>
				<geometry>
					<mesh filename="package://plastun_description/meshes/STL_min/wheel.stl" scale="1.0 1.0 1.0"/>
				</geometry>
			</visual>
		</link>

		<joint name="wheel_${rev}_${num}" type="revolute">
			<parent link="chassis"/>
			<child link="wheel_${prefix}_${num}"/>
			<origin rpy="0       0      0" xyz="${0.1405513 + (num - 1) * between_wheels} ${y_wheel * side}   ${z_wheel}"/>
			<axis xyz="0 -1  0"/>
			<limit effort="-1" lower="-1e+50" upper="1e+50" velocity="100"/>
		</joint>
	</xacro:macro>

	<xacro:macro name="transmission_wheel" params="rev num side_name">
		<transmission name="wheel_${side_name}_${num}">
			<type>transmission_interface/SimpleTransmission</type>
			<joint name="wheel_${rev}_${num}">
				<hardwareInterface>EffortJointInterface</hardwareInterface>
			</joint>
			<actuator name="wh_${side_name}_${num}">
				<hardwareInterface>EffortJointInterface</hardwareInterface>
				<mechanicalReduction>1</mechanicalReduction>
			</actuator>
		</transmission>
	</xacro:macro>


	<xacro:macro name="camer" params="num side">
		<link name="camera_${num}">
			<inertial>
				<mass value="0.001"/>
				<origin rpy="0  0  0" xyz="-0.000018  -0.000225  0.060158"/>
				<inertia ixx="0.00034961" ixy="0" ixz="0" iyy="0.00243426" iyz="0" izz="0.0027544"/>
			</inertial>
			<collision >
				<origin rpy="0  0  0" xyz="0  0  0"/>
				<geometry>
					<mesh filename="package://plastun_description/meshes/STL_min/camera.stl" scale="1 1 1"/>
				</geometry>
			</collision>
			<visual >
				<origin rpy="0  0  0" xyz="0  0  0"/>
				<geometry>
					<mesh filename="package://plastun_description/meshes/STL_min/camera.stl" scale="1 1 1"/>
				</geometry>
			</visual>
		</link>

		<joint name="turrel_vverh_camera_${num}_fixed" type="revolute">
			<parent link="turrel_vverh"/>
			<child link="camera_${num}"/>
			<origin rpy="0       0       0" xyz="${x_camera}  ${y_camera * side} ${z_camera}"/>
			<axis xyz="0  0  1"/>
			<limit effort="0" lower="0" upper="0" velocity="0"/>
		</joint>
	</xacro:macro>

	<xacro:macro name="transmission_camera" params="num">
		<transmission name="camer_${num}">
			<type>transmission_interface/SimpleTransmission</type>
			<joint name="turrel_vverh_camera_${num}_fixed">
				<hardwareInterface>EffortJointInterface</hardwareInterface>
			</joint>
			<actuator name="cam_${num}">
				<hardwareInterface>EffortJointInterface</hardwareInterface>
				<mechanicalReduction>1</mechanicalReduction>
			</actuator>
		</transmission>
	</xacro:macro>


	<link name="base_link"/>

	<joint name="chassis_base_link_fixed" type="fixed">
		<parent link="base_link"/>
		<child link="chassis"/>
	</joint>

	<link name="chassis">
		<inertial>
			<mass value="30"/>
			<origin rpy="0  0  0" xyz="0.436419 -0.000612  0.228789"/>
			<inertia ixx="0.166667" ixy="0" ixz="0" iyy="0.166667" iyz="0" izz="0.166667"/>
		</inertial>
		<collision >
			<origin rpy="0  0  0" xyz="0 0  0"/>
			<geometry>
				<mesh filename="package://plastun_description/meshes/STL_min/chassis.stl" scale="1.0 1.0 1.0"/>
			</geometry>
		</collision>
		<visual >
			<origin rpy="0  0  0" xyz="0 0  0"/>
			<geometry>
				<mesh filename="package://plastun_description/meshes/STL_min/chassis.stl" scale="1 1 1"/>
			</geometry>
			<material name="green"/>
		</visual>
	</link>


	<!--laser sensors -->
	<link name="lazer_ukazka">
		<inertial>
			<mass value="0.001"/>
			<origin rpy="0  0  0" xyz="-0.017806  0  0.027446"/>
			<inertia ixx="0.0" ixy="0" ixz="0" iyy="0.0" iyz="0" izz="0.0"/>
		</inertial>
		<collision >
			<origin rpy="0  0  0" xyz="0  0  0"/>
			<geometry>
				<mesh filename="package://plastun_description/meshes/STL_min/lazer_ukazka.stl" scale="1.0 1.0 1.0"/>
			</geometry>
		</collision>
		<visual >
			<origin rpy="0  0  0" xyz="0  0  0"/>
			<geometry>
				<mesh filename="package://plastun_description/meshes/STL_min/lazer_ukazka.stl" scale="1.0 1.0 1.0"/>
			</geometry>
			<material name="white"/>
		</visual>
	</link>

	<link name="hokuyo">
		<inertial>
			<mass value="0.3"/>
			<origin rpy="0  0  0" xyz="-0.000001  0  0.053927"/>
			<inertia ixx="0.166667" ixy="0" ixz="0" iyy="0.166667" iyz="0" izz="0.166667"/>
		</inertial>
		<collision >
			<origin rpy="0  0  0" xyz="0    0    0.05"/>
			<geometry>
				<box size="0.06524 0.079833 0.102579"/>
			</geometry>
		</collision>
		<visual >
			<origin rpy="0  0  0" xyz="0  0  0"/>
			<geometry>
				<mesh filename="package://plastun_description/meshes/STL_min/hokuyo.stl" scale="1 1 1"/>
			</geometry>
		</visual>
	</link>


	<!-- Turrel -->
	<link name="turrel_vniz">
		<inertial>
			<mass value="1"/>
			<origin rpy="0  0  0" xyz="-0.000002  0  0.072908"/>
			<inertia ixx="0.166667" ixy="0" ixz="0" iyy="0.166667" iyz="0" izz="0.166667"/>
		</inertial>
		<collision >
			<origin rpy="0  0  0" xyz="0  0  0"/>
			<geometry>
				<mesh filename="package://plastun_description/meshes/STL_min/turrel_vniz.stl" scale="1.0 1.0 1.0"/>
			</geometry>
		</collision>
		<visual >
			<origin rpy="0  0  0" xyz="0  0  0"/>
			<geometry>
				<mesh filename="package://plastun_description/meshes/STL_min/turrel_vniz.stl" scale="1.0 1.0 1.0"/>
			</geometry>
			<material name="white"/>
		</visual>
	</link>

	<link name="turrel_sered">
		<inertial>
			<mass value="1"/>
			<origin rpy="0  0  0" xyz="0  0  0.089664"/>
			<inertia ixx="0.166667" ixy="0" ixz="0" iyy="0.166667" iyz="0" izz="0.166667"/>
		</inertial>
		<collision >
			<origin rpy="0  0  0" xyz="0  0  0"/>
			<geometry>
				<mesh filename="package://plastun_description/meshes/STL_min/turrel_sered.stl" scale="1.0 1.0 1.0"/>
			</geometry>
		</collision>
		<visual >
			<origin rpy="0  0  0" xyz="0  0  0"/>
			<geometry>
				<mesh filename="package://plastun_description/meshes/STL_min/turrel_sered.stl" scale="1.0 1.0 1.0"/>
			</geometry>
			<material name="brown"/>
		</visual>
	</link>

	<link name="turrel_vverh">
		<inertial>
			<mass value="1"/>
			<origin rpy="0  0  0" xyz="0    -0.005000   0.051671"/>
			<inertia ixx="0.166667" ixy="0" ixz="0" iyy="0.166667" iyz="0" izz="0.166667"/>
		</inertial>
		<collision >
			<origin rpy="0  0  0" xyz="0    0   0"/>
			<geometry>
				<mesh filename="package://plastun_description/meshes/STL_min/turrel_vverh.stl" scale="1.0 1.0 1.0"/>
			</geometry>
		</collision>
		<visual >
			<origin rpy="0  0  0" xyz="0    0   0"/>
			<geometry>
				<mesh filename="package://plastun_description/meshes/STL_min/turrel_vverh.stl" scale="1.0 1.0 1.0"/>
			</geometry>
			<material name="blue"/>
		</visual>
	</link>


	<!--cameras (links and joints(fix with turrel_verh)) -->
	<xacro:camer num="1" side="-1"/>
	<xacro:camer num="2" side="1"/>


	<!-- wheels (links and joints(revolute, parrent - chassis))-->
	<xacro:wheel prefix="left" num="1" side="-1" rev="lev"/>
	<xacro:wheel prefix="left" num="2" side="-1" rev="lev"/>
	<xacro:wheel prefix="left" num="3" side="-1" rev="lev"/>
	<xacro:wheel prefix="right" num="1" side="1" rev="prav"/>
	<xacro:wheel prefix="right" num="2" side="1" rev="prav"/>
	<xacro:wheel prefix="right" num="3" side="1" rev="prav"/>


	<!--fix'es joints -->
	<joint name="camera_1_lazer_ukazka_fixed" type="revolute">
		<parent link="camera_1"/>
		<child link="lazer_ukazka"/>
		<origin rpy="0       0      0" xyz="-0.04766  0.00111  0.10548"/>
		<axis xyz="0  0  1"/>
		<limit effort="0" lower="0" upper="0" velocity="0"/>
	</joint>

	<joint name="chassis_hokuyo_fixed" type="revolute">
		<parent link="chassis"/>
		<child link="hokuyo"/>
		<origin rpy="0       0       0" xyz="0.14586  0.083   0.365"/>
		<axis xyz="0  0  1"/>
		<limit effort="0" lower="0" upper="0" velocity="0"/>
	</joint>

	<joint name="chassis_turrel_vniz_fixed" type="fixed">
		<parent link="chassis"/>
		<child link="turrel_vniz"/>
		<origin rpy="0 0  0" xyz="0.255 0  0.37358"/>
		<axis xyz="0  0  0"/>
		<limit effort="0" lower="0" upper="0" velocity="0"/>
	</joint>


	<!-- revolute joints -->  
	<joint name="turrel_vniz_turrel_sered_revolute" type="revolute">
		<parent link="turrel_vniz"/>
		<child link="turrel_sered"/>
		<origin rpy="0  0   0" xyz="0 0  0.13474"/>
		<axis xyz="0  0  1"/>
		<limit effort="1" lower="-7" upper="7" velocity="10"/>
	</joint>

	<joint name="turrel_sered_turrel_vverh_up_to_down" type="revolute">
		<parent link="turrel_sered"/>
		<child link="turrel_vverh"/>
		<origin rpy="0   0   0" xyz="0  0.005 0.1"/>
		<axis xyz="0  1  0"/>
		<limit effort="1" lower="-1" upper="1" velocity="100"/>
	</joint>


	<!--transmitions-->
	<transmission name="turrel_revol">
		<type>transmission_interface/SimpleTransmission</type>
		<joint name="turrel_vniz_turrel_sered_revolute">
			<hardwareInterface>EffortJointInterface</hardwareInterface>
		</joint>
		<actuator name="tl_rev">
			<hardwareInterface>EffortJointInterface</hardwareInterface>
			<mechanicalReduction>1</mechanicalReduction>
		</actuator>
	</transmission>

	<transmission name="turrel_up_to_down">
		<type>transmission_interface/SimpleTransmission</type>
		<joint name="turrel_sered_turrel_vverh_up_to_down">
			<hardwareInterface>EffortJointInterface</hardwareInterface>
		</joint>
		<actuator name="tl_ud">
			<hardwareInterface>EffortJointInterface</hardwareInterface>
			<mechanicalReduction>1</mechanicalReduction>
		</actuator>
	</transmission>

	<transmission name="chassis_hokuyo_fix">
		<type>transmission_interface/SimpleTransmission</type>
		<joint name="chassis_hokuyo_fixed">
			<hardwareInterface>EffortJointInterface</hardwareInterface>
		</joint>
		<actuator name="chas_hok_fix">
			<hardwareInterface>EffortJointInterface</hardwareInterface>
			<mechanicalReduction>1</mechanicalReduction>
		</actuator>
	</transmission>

	<xacro:transmission_wheel num="1" side_name="l" rev="lev"/>
	<xacro:transmission_wheel num="2" side_name="l" rev="lev"/>
	<xacro:transmission_wheel num="3" side_name="l" rev="lev"/>
	<xacro:transmission_wheel num="1" side_name="r" rev="prav"/>
	<xacro:transmission_wheel num="2" side_name="r" rev="prav"/>
	<xacro:transmission_wheel num="3" side_name="r" rev="prav"/>

	<xacro:transmission_camera num="1"/>
	<xacro:transmission_camera num="2"/>


	<transmission name="camera_1_ukaz_fix">
		<type>transmission_interface/SimpleTransmission</type>
		<joint name="camera_1_lazer_ukazka_fixed">
			<hardwareInterface>EffortJointInterface</hardwareInterface>
		</joint>
		<actuator name="cam_uk_fix">
			<hardwareInterface>EffortJointInterface</hardwareInterface>
			<mechanicalReduction>1</mechanicalReduction>
		</actuator>
	</transmission>

</robot>
