<?xml version="1.0" ?>

<robot name="MRC_&quot;Plastun&quot;">

  <link name="chassis">
    <inertial>
      <mass value="30"/>
      <origin rpy="0  0  0" xyz="0.32045 -0.00448  0.06272"/>
      <inertia ixx="0.166667" ixy="0" ixz="0" iyy="0.166667" iyz="0" izz="0.166667"/>
    </inertial>
    <collision >
      <origin rpy="0  0  0" xyz="0.32045 0  0.06272"/>
      <geometry>
        <mesh filename="package://plastun_description/meshes/STL_min/chassis.stl" scale="1.0 1.0 1.0"/>
      </geometry>
    </collision>
    <visual >
      <origin rpy="0  0  0" xyz="0.32045 0  0.06272"/>
      <geometry>
        <mesh filename="package://plastun_description/meshes/STL_min/chassis.stl" scale="1 1 1"/>
      </geometry>
    </visual>
  </link>

<!-- wheels -->
    <link name="wheel_left_1">
    <inertial>
      <mass value="1"/>
      <origin rpy="0  0  0" xyz="0  0  0"/>
      <inertia ixx="0.166667" ixy="0" ixz="0" iyy="0.166667" iyz="0" izz="0.166667"/>
    </inertial>
    <collision >
      <origin rpy="1.5708  0      0" xyz="0  0  0"/>
      <geometry>
        <cylinder length="0.09" radius="0.096"/>
      </geometry>
    </collision>
    <visual >
      <origin rpy="0  0  0" xyz="0  0  0"/>
      <geometry>
        <mesh filename="package://plastun_description/meshes/STL_min/wheel.stl" scale="1.0 1.0 1.0"/>
      </geometry>
    </visual>
  </link>

  <link name="wheel_left_2">
    <inertial>
      <mass value="1"/>
      <origin rpy="0  0  0" xyz="0  0  0"/>
      <inertia ixx="0.166667" ixy="0" ixz="0" iyy="0.166667" iyz="0" izz="0.166667"/>
    </inertial>
    <collision >
      <origin rpy="1.5708  0      0" xyz="0  0  0"/>
      <geometry>
        <cylinder length="0.09" radius="0.096"/>
      </geometry>
    </collision>
    <visual >
      <origin rpy="0  0  0" xyz="0  0  0"/>
      <geometry>
        <mesh filename="package://plastun_description/meshes/STL_min/wheel.stl" scale="1.0 1.0 1.0"/>
      </geometry>
    </visual>
  </link>

  <link name="wheel_left_3">
    <inertial>
      <mass value="1"/>
      <origin rpy="0  0  0" xyz="0  0  0"/>
      <inertia ixx="0.166667" ixy="0" ixz="0" iyy="0.166667" iyz="0" izz="0.166667"/>
    </inertial>
    <collision>
      <origin rpy="1.5708  0      0" xyz="0  0  0"/>
      <geometry>
        <cylinder length="0.09" radius="0.096"/>
      </geometry>
    </collision>
    <visual >
      <origin rpy="0  0  0" xyz="0  0  0"/>
      <geometry>
        <mesh filename="package://plastun_description/meshes/STL_min/wheel.stl" scale="1.0 1.0 1.0"/>
      </geometry>
    </visual>
  </link>
  <link name="wheel_right_1">
    <inertial>
      <mass value="1"/>
      <origin rpy="0  0  0" xyz="0  0  0"/>
      <inertia ixx="0.166667" ixy="0" ixz="0" iyy="0.166667" iyz="0" izz="0.166667"/>
    </inertial>
    <collision >
      <origin rpy="1.5708  0      0" xyz="0  0  0"/>
      <geometry>
        <cylinder length="0.09" radius="0.096"/>
      </geometry>
    </collision>
    <visual >
      <origin rpy="0  0  0" xyz="0  0  0"/>
      <geometry>
        <mesh filename="package://plastun_description/meshes/STL_min/wheel.stl" scale="1.0 1.0 1.0"/>
      </geometry>
    </visual>
  </link>

  <link name="wheel_right_2">
    <inertial>
      <mass value="1"/>
      <origin rpy="0  0  0" xyz="0  0  0"/>
      <inertia ixx="0.166667" ixy="0" ixz="0" iyy="0.166667" iyz="0" izz="0.166667"/>
    </inertial>
    <collision >
      <origin rpy="1.5708  0      0" xyz="0  0  0"/>
      <geometry>
        <cylinder length="0.09" radius="0.096"/>
      </geometry>
    </collision>
    <visual >
      <origin rpy="0  0  0" xyz="0  0  0"/>
      <geometry>
        <mesh filename="package://plastun_description/meshes/STL_min/wheel.stl" scale="1.0 1.0 1.0"/>
      </geometry>
    </visual>
  </link>

  <link name="wheel_right_3">
    <inertial>
      <mass value="1"/>
      <origin rpy="0  0  0" xyz="0  0  0"/>
      <inertia ixx="0.166667" ixy="0" ixz="0" iyy="0.166667" iyz="0" izz="0.166667"/>
    </inertial>
    <collision >
      <origin rpy="1.5708  0      0" xyz="0  0  0"/>
      <geometry>
        <cylinder length="0.09" radius="0.096"/>
      </geometry>
    </collision>
    <visual >
      <origin rpy="0  0  0" xyz="0  0  0"/>
      <geometry>
        <mesh filename="package://plastun_description/meshes/STL_min/wheel.stl" scale="1.0 1.0 1.0"/>
      </geometry>
    </visual>
  </link>

<!-- cameras and sensors -->
  <link name="lazer_ukazka">
    <inertial>
      <mass value="0.5"/>
      <origin rpy="0  0  0" xyz="0  0  0"/>
      <inertia ixx="0.166667" ixy="0" ixz="0" iyy="0.166667" iyz="0" izz="0.166667"/>
    </inertial>
    <collision >
      <origin rpy="0  0  0" xyz="0  0  0"/>
      <geometry>
        <mesh filename="package://plastun_description/meshes/STL_min/lazer_ukazka.stl" scale="1.0 1.0 1.0"/>
      </geometry>
    </collision>
    <visual >
      <origin rpy="0  0  0" xyz="0  0  0"/>
      <geometry>
        <mesh filename="package://plastun_description/meshes/STL_min/lazer_ukazka.stl" scale="1.0 1.0 1.0"/>
      </geometry>
    </visual>
  </link>

  <link name="camera_1">
    <inertial>
      <mass value="0.0290342"/>
      <origin rpy="0  0  0" xyz="0  0  0"/>
      <inertia ixx="0.00034961" ixy="0" ixz="0" iyy="0.00243426" iyz="0" izz="0.0027544"/>
    </inertial>
    <collision >
       <origin rpy="0  0  0" xyz="0  0  0"/>
      <geometry>
        <mesh filename="package://plastun_description/meshes/STL_min/camera.stl" scale="1 1 1"/>
      </geometry>
    </collision>
    <visual >
      <origin rpy="0  0  0" xyz="0  0  0"/>
      <geometry>
        <mesh filename="package://plastun_description/meshes/STL_min/camera.stl" scale="1 1 1"/>
      </geometry>
    </visual>
  </link>

  <link name="camera_2">
    <inertial>
      <mass value="0.00092334"/>
      <origin rpy="0  0  0" xyz="0  0  0"/>
      <inertia ixx="9.8e-07" ixy="0" ixz="0" iyy="2.45e-06" iyz="0" izz="2.95e-06"/>
    </inertial>
    <collision >
    <origin rpy="0  0  0" xyz="0  0  0"/>
      <geometry>
        <mesh filename="package://plastun_description/meshes/STL_min/camera.stl" scale="1 1 1"/>
      </geometry>
    </collision>
    <visual >
      <origin rpy="0  0  0" xyz="0  0  0"/>
      <geometry>
        <mesh filename="package://plastun_description/meshes/STL_min/camera.stl" scale="1 1 1"/>
      </geometry>
    </visual>
  </link>

  <link name="hokuyo">
    <inertial>
      <mass value="0.00014924"/>
      <origin rpy="0  0  0" xyz="0  0  0"/>
      <inertia ixx="2.7e-07" ixy="0" ixz="0" iyy="1.9e-07" iyz="0" izz="8e-08"/>
    </inertial>
    <collision >
      <origin rpy="0  0  0" xyz="0    0    0.05"/>
      <geometry>
        <box size="0.06524 0.079833 0.102579"/>
      </geometry>
    </collision>
    <visual >
      <origin rpy="0  0  0" xyz="0  0  0"/>
      <geometry>
        <mesh filename="package://plastun_description/meshes/STL_min/hokuyo.stl" scale="1 1 1"/>
      </geometry>
    </visual>
  </link>

<!-- Turrel -->
    <link name="turrel_vniz">
    <inertial>
      <mass value="1"/>
      <origin rpy="0  0  0" xyz="0  0  0"/>
      <inertia ixx="0.166667" ixy="0" ixz="0" iyy="0.166667" iyz="0" izz="0.166667"/>
    </inertial>
    <collision >
      <origin rpy="0  0  0" xyz="0  0  0"/>
      <geometry>
        <mesh filename="package://plastun_description/meshes/STL_min/turrel_vniz.stl" scale="1.0 1.0 1.0"/>
      </geometry>
    </collision>
    <visual >
      <origin rpy="0  0  0" xyz="0  0  0"/>
      <geometry>
        <mesh filename="package://plastun_description/meshes/STL_min/turrel_vniz.stl" scale="1.0 1.0 1.0"/>
      </geometry>

    </visual>
  </link>

  <link name="turrel_sered">
    <inertial>
      <mass value="1"/>
      <origin rpy="0  0  0" xyz="0  0  0"/>
      <inertia ixx="0.166667" ixy="0" ixz="0" iyy="0.166667" iyz="0" izz="0.166667"/>
    </inertial>
    <collision >
      <origin rpy="0  0  0" xyz="0  0  0"/>
      <geometry>
        <mesh filename="package://plastun_description/meshes/STL_min/turrel_sered.stl" scale="1.0 1.0 1.0"/>
      </geometry>
    </collision>
    <visual >
      <origin rpy="0  0  0" xyz="0  0  0"/>
      <geometry>
        <mesh filename="package://plastun_description/meshes/STL_min/turrel_sered.stl" scale="1.0 1.0 1.0"/>
      </geometry>

    </visual>
  </link>

  <link name="turrel_vverh">
    <inertial>
      <mass value="1"/>
      <origin rpy="0  0  0" xyz="0    0   0"/>
      <inertia ixx="0.166667" ixy="0" ixz="0" iyy="0.166667" iyz="0" izz="0.166667"/>
    </inertial>
    <collision >
      <origin rpy="0  0  0" xyz="0    0   0"/>
      <geometry>
        <mesh filename="package://plastun_description/meshes/STL_min/turrel_vverh.stl" scale="1.0 1.0 1.0"/>
      </geometry>
    </collision>
    <visual >
      <origin rpy="0  0  0" xyz="0    0   0"/>
      <geometry>
        <mesh filename="package://plastun_description/meshes/STL_min/turrel_vverh.stl" scale="1.0 1.0 1.0"/>
      </geometry>

    </visual>
  </link>



<!-- wheels'es joints -->
  <joint name="wheel_lev_1" type="revolute">
    <parent link="chassis"/>
    <child link="wheel_left_1"/>
    <origin rpy="0       0      0" xyz="0.36566 -0.20499   0.15237"/>
    <axis xyz="0 -1  0"/>
   <!-- <limit effort="-1.0" lower="-1.79769e+308" upper="1.79769e+308" velocity="-1.0"/> -->
   <limit effort="-1" lower="-1e+50" upper="1e+50" velocity="100"/>
  </joint>

  <joint name="wheel_lev_2" type="revolute">
    <parent link="chassis"/>
    <child link="wheel_left_2"/>
    <origin rpy="0       0      0" xyz="0.13874 -0.20499  0.15237"/>
    <axis xyz="0 -1  0"/>
      <!-- <limit effort="-1.0" lower="-1.79769e+308" upper="1.79769e+308" velocity="-1.0"/> -->
   <limit effort="-1" lower="-1e+50" upper="1e+50" velocity="100"/>
  </joint>

  <joint name="wheel_lev_3" type="revolute">
    <parent link="chassis"/>
    <child link="wheel_left_3"/>
    <origin rpy="0       0      0" xyz="0.58393 -0.20499  0.15237"/>
    <axis xyz="0 -1  0"/>
      <!-- <limit effort="-1.0" lower="-1.79769e+308" upper="1.79769e+308" velocity="-1.0"/> -->
   <limit effort="-1" lower="-1e+50" upper="1e+50" velocity="100"/>
  </joint>

  <joint name="wheel_prav_1" type="revolute">
    <parent link="chassis"/>
    <child link="wheel_right_1"/>
    <origin rpy="0       0      0" xyz="0.13874  0.20499  0.15237"/>
    <axis xyz="0 -1  0"/>
      <!-- <limit effort="-1.0" lower="-1.79769e+308" upper="1.79769e+308" velocity="-1.0"/> -->
   <limit effort="-1" lower="-1e+50" upper="1e+50" velocity="100"/>
  </joint>

  <joint name="wheel_prav_2" type="revolute">
    <parent link="chassis"/>
    <child link="wheel_right_2"/>
    <origin rpy="0       0      0" xyz="0.36566  0.20499  0.15237"/>
    <axis xyz="0 -1  0"/>
      <!-- <limit effort="-1.0" lower="-1.79769e+308" upper="1.79769e+308" velocity="-1.0"/> -->
   <limit effort="-1" lower="-1e+50" upper="1e+50" velocity="100"/>
  </joint>

  <joint name="wheel_prav_3" type="revolute">
    <parent link="chassis"/>
    <child link="wheel_right_3"/>
    <origin rpy="0  0  0" xyz="0.58393  0.20499  0.15237"/>
    <axis xyz="0 -1  0"/>
       <!-- <limit effort="-1.0" lower="-1.79769e+308" upper="1.79769e+308" velocity="-1.0"/> -->
   <limit effort="-1" lower="-1e+50" upper="1e+50" velocity="100"/>
  </joint>

<!--fix'es joints -->
  <joint name="camera_1 _ lazer_ukazka fixed" type="fixed">
    <parent link="camera_1"/>
    <child link="lazer_ukazka"/>
    <origin rpy="0       0      0" xyz="-0.04766  0.00111  0.10548"/>
    <axis xyz="0  0  0"/>
    <limit effort="0" lower="0" upper="0" velocity="0"/>
  </joint>

  <joint name="turrel_vverh _ camera_1 fixed" type="fixed">
    <parent link="turrel_vverh"/>
    <child link="camera_1"/>
    <origin rpy="0       0       0" xyz="-0.07152 -0.21215 -0.017"/>
    <axis xyz="0  0  0"/>
    <limit effort="0" lower="0" upper="0" velocity="0"/>
  </joint>

  <joint name="turrel_vverh _ camera_2 fixed" type="fixed">
    <parent link="turrel_vverh"/>
    <child link="camera_2"/>
    <origin rpy="0       0       0" xyz="-0.07152  0.21176 -0.017"/>
    <axis xyz="0  0  0"/>
    <limit effort="0" lower="0" upper="0" velocity="0"/>
  </joint>

 <joint name="chassis _ turrel_vniz fixed" type="fixed">
    <parent link="chassis"/>
    <child link="turrel_vniz"/>
    <origin rpy="0 0  0" xyz="0.25857 -0.01238  0.42994"/>
    <axis xyz="0  0  0"/>
    <limit effort="0" lower="0" upper="0" velocity="0"/>
  </joint>

  <joint name="chassis _ hokuyo fixed" type="fixed">
    <parent link="chassis"/>
    <child link="hokuyo"/>
    <origin rpy="0       0       0" xyz="0.15582  0.0808   0.42783"/>
    <axis xyz="0  0  0"/>
    <limit effort="0" lower="0" upper="0" velocity="0"/>
  </joint>

<!-- revolute joints -->  
  <joint name="turrel_vniz _ turrel_sered revolute" type="revolute">
    <parent link="turrel_vniz"/>
    <child link="turrel_sered"/>
    <origin rpy="0  0   0" xyz="0.00045 -0.00033  0.13474"/>
    <axis xyz="0  0  1"/>
     <limit effort="2" lower="-5" upper="5" velocity="100"/>
  </joint>

  <joint name="turrel_sered _ turrel_vverh up-to-down" type="revolute">
    <parent link="turrel_sered"/>
    <child link="turrel_vverh"/>
    <origin rpy="0   0   0" xyz="0.00306  0.00468  0.12878"/>
    <axis xyz="0  1  0"/>
     <limit effort="1" lower="-1" upper="1" velocity="100"/>
  </joint>

<!-- plugins -->
  <gazebo>
    <plugin filename="libgazebo_ros_control.so" name="gazebo_ros_control">
      <robotNamespace>/plastun</robotNamespace>
    </plugin>
  </gazebo>

<!--colors -->
  <gazebo reference="chassis">
    
    
    <material>Gazebo/Grey</material>
    
  </gazebo>

    <gazebo reference="turrel_vniz">
    
    
    <material>Gazebo/Grey</material>
    
  </gazebo>

    <gazebo reference="turrel_sered">
    
    
    <material>Gazebo/Grey</material>
    
  </gazebo>

    <gazebo reference="turrel_vverh">
    
    
    <material>Gazebo/Grey</material>
    
  </gazebo>

    <gazebo reference="hokuyo">
    
    
    <material>Gazebo/Grey</material>
    
  </gazebo>

      <gazebo reference="camera_1">
    
    
    <material>Gazebo/Grey</material>
    
  </gazebo>

      <gazebo reference="camera_2">
    
    
    <material>Gazebo/Grey</material>
    
  </gazebo>

<!-- sensors -->
  <gazebo reference="camera_1">
        <sensor name='camera' type='camera'>
          <pose>0 0.2 0.01 -1.5708 0.000000 3,1416</pose>
          <camera name='__default__'>
            <horizontal_fov>1.012300</horizontal_fov>
            <image>
              <width>320</width>
              <height>200</height>
            </image>
            <clip>
              <near>0.001000</near>
              <far>100.000000</far>
            </clip>
          </camera>
          <always_on>1</always_on>
          <update_rate>30.000000</update_rate>
          <visualize>1</visualize>
          <plugin name="camera_controller" filename="libgazebo_ros_camera.so">
            <alwaysOn>true</alwaysOn>
            <updateRate>30</updateRate>
            <cameraName>camera_1</cameraName>
            <robotNamespace>plastun</robotNamespace>
            <imageTopicName>image_raw_1</imageTopicName>
            <cameraInfoTopicName>camera_info_1</cameraInfoTopicName>
            <frameName>camera_link</frameName>
            <hackBaseline>0.07</hackBaseline>
            <distortionK1>0.0</distortionK1>
            <distortionK2>0.0</distortionK2>
            <distortionK3>0.0</distortionK3>
            <distortionT1>0.0</distortionT1>
            <distortionT2>0.0</distortionT2>
          </plugin>        
      </sensor>
</gazebo>

<gazebo reference="camera_2">
        <sensor name='camera' type='camera'>
          <pose>0 0.2 0.01 -1.5708 0.000000 3,1416</pose>
          <camera name='__default__'>
            <horizontal_fov>1.012300</horizontal_fov>
            <image>
              <width>320</width>
              <height>200</height>
            </image>
            <clip>
              <near>0.001000</near>
              <far>100.000000</far>
            </clip>
          </camera>
          <always_on>1</always_on>
          <update_rate>30.000000</update_rate>
          <visualize>1</visualize>
          <plugin name="camera_controller" filename="libgazebo_ros_camera.so">
            <alwaysOn>true</alwaysOn>
            <updateRate>30</updateRate>
            <cameraName>camera_2</cameraName>
            <imageTopicName>image_raw_2</imageTopicName>
            <robotNamespace>plastun</robotNamespace>
            <cameraInfoTopicName>camera_info_2</cameraInfoTopicName>
            <frameName>camera_link</frameName>
            <hackBaseline>0.07</hackBaseline>
            <distortionK1>0.0</distortionK1>
            <distortionK2>0.0</distortionK2>
            <distortionK3>0.0</distortionK3>
            <distortionT1>0.0</distortionT1>
            <distortionT2>0.0</distortionT2>
          </plugin>        
      </sensor>
</gazebo>

 <gazebo reference="hokuyo">
    <sensor type="gpu_ray" name="head_hokuyo_sensor">
      <pose>0 0 0.5 0 0 3,1416</pose>
      <visualize>true</visualize>
      <update_rate>40</update_rate>
      <ray>
        <scan>
          <horizontal>
            <samples>720</samples>
            <resolution>1</resolution>
            <min_angle>-1.470796</min_angle>
            <max_angle>1.470796</max_angle>
          </horizontal>
        </scan>
        <range>
          <min>0.10</min>
          <max>30.0</max>
          <resolution>0.01</resolution>
        </range>
        <noise>
          <type>gaussian</type>
          <!-- Noise parameters based on published spec for Hokuyo laser
               achieving "+-30mm" accuracy at range < 10m.  A mean of 0.0m and
               stddev of 0.01m will put 99.7% of samples within 0.03m of the true
               reading. -->
          <mean>0.0</mean>
          <stddev>0.01</stddev>
        </noise>
      </ray>
      <plugin name="gazebo_ros_head_hokuyo_controller" filename="libgazebo_ros_gpu_laser.so">
        <robotNamespace>plastun</robotNamespace>
        <topicName>laser/scan</topicName>
        <frameName>hokuyo_link</frameName>
      </plugin>
    </sensor>
  </gazebo>

<gazebo reference="lazer_ukazka">
    <sensor type="gpu_ray" name="head_hokuyo_sensor">
      <pose>0 0.5 0.2 0 0 3.14</pose>
      <visualize>true</visualize>
      <update_rate>40</update_rate>
      <ray>
        <scan>
          <horizontal>
            <samples>2</samples>
            <resolution>1</resolution>
            <min_angle>-0.005</min_angle>
            <max_angle>0.005</max_angle>
          </horizontal>
        </scan>
        <range>
          <min>0.10</min>
          <max>30.0</max>
          <resolution>0.01</resolution>
        </range>
        <noise>
          <type>gaussian</type>
          <!-- Noise parameters based on published spec for Hokuyo laser
               achieving "+-30mm" accuracy at range < 10m.  A mean of 0.0m and
               stddev of 0.01m will put 99.7% of samples within 0.03m of the true
               reading. -->
          <mean>0.0</mean>
          <stddev>0.01</stddev>
        </noise>
      </ray>
      <plugin name="gazebo_ros_head_hokuyo_controller" filename="libgazebo_ros_gpu_laser.so">
        <robotNamespace>plastun</robotNamespace>
        <topicName>laser/scan_ukaz</topicName>
        <frameName>ukaz_link</frameName>
      </plugin>
    </sensor>
  </gazebo>

<gazebo>
  <plugin name="skid_steer_drive_controller" filename="libgazebo_ros_skid_steer_drive.so">
    <updateRate>100.0</updateRate>
    <robotNamespace>plastun</robotNamespace>
    <leftFrontJoint>wheel_lev_1</leftFrontJoint>
    <rightFrontJoint>wheel_prav_1</rightFrontJoint>
    <leftRearJoint>wheel_lev_3</leftRearJoint>
    <rightRearJoint>wheel_prav_3</rightRearJoint>
    <wheelSeparation>0.4</wheelSeparation>
    <wheelDiameter>0.192</wheelDiameter>
    <robotBaseFrame>chassis</robotBaseFrame>
    <torque>20</torque>
    <commandTopic>cmd_vel</commandTopic>
    <odometryTopic>odom</odometryTopic>
    <odometryFrame>odom</odometryFrame>
    <broadcastTF>false</broadcastTF>
  </plugin>
</gazebo>



</robot>
