<?xml version="1.0" ?>
<!-- =================================================================================== -->
<!-- |    This document was autogenerated by xacro from plastun.xacro                  | -->
<!-- |    EDITING THIS FILE BY HAND IS NOT RECOMMENDED                                 | -->
<!-- =================================================================================== -->
<robot name="MRC_Plastun" xmlns:xacro="http://www.ros.org/wiki/xacro">
  <material name="black">
    <color rgba="0.0 0.0 0.0 1.0"/>
  </material>
  <material name="blue">
    <color rgba="0.0 0.0 0.8 1.0"/>
  </material>
  <material name="green">
    <color rgba="0.0 0.8 0.0 1.0"/>
  </material>
  <material name="grey">
    <color rgba="0.2 0.2 0.2 1.0"/>
  </material>
  <material name="orange">
    <color rgba="1.0 0.423529411765 0.0392156862745 1.0"/>
  </material>
  <material name="brown">
    <color rgba="0.870588235294 0.811764705882 0.764705882353 1.0"/>
  </material>
  <material name="red">
    <color rgba="0.8 0.0 0.0 1.0"/>
  </material>
  <material name="white">
    <color rgba="1.0 1.0 1.0 1.0"/>
  </material>
  <link name="base_link"/>
  <joint name="base_link_chassis_fixed" type="fixed">
    <parent link="base_link"/>
    <child link="chassis"/>
  </joint>
  <link name="chassis">
    <inertial>
      <mass value="35"/>
      <origin rpy="0  0  0" xyz="0.289120720 -0.000018254  0.186368419"/>
      <inertia ixx="3.1081800" ixy="-0.25460189" ixz="2.0318174" iyy="6.3787776" iyz="0.16417863" izz="5.3316425"/>
    </inertial>
    <collision>
      <origin rpy="0  0  0" xyz="0 0  0.0435"/>
      <geometry>
        <mesh filename="package://plastun_description/meshes/STL_min/chassis.stl" scale="1.0 1.0 1.0"/>
      </geometry>
    </collision>
    <visual>
      <origin rpy="0  0  0" xyz="0 0  0.0435"/>
      <geometry>
        <mesh filename="package://plastun_description/meshes/STL_min/chassis.stl" scale="1 1 1"/>
      </geometry>
      <material name="green"/>
    </visual>
  </link>
  <!--laser sensors -->
  <link name="lazer_ukazka">
    <inertial>
      <mass value="0.001"/>
      <origin rpy="0  0  0" xyz="0.017977372  -0.000001823  0.034613516"/>
      <inertia ixx="0.0" ixy="0" ixz="0" iyy="0.0" iyz="0" izz="0.0"/>
    </inertial>
    <visual>
      <origin rpy="0  0  0" xyz="-0.171  -0  -0.045"/>
      <geometry>
        <mesh filename="package://plastun_description/meshes/STL_min/lazer_ukazka.stl" scale="1.0 1.0 1.0"/>
      </geometry>
      <material name="white"/>
    </visual>
  </link>
  <link name="hokuyo">
    <inertial>
      <mass value="0.3"/>
      <origin rpy="0  0  0" xyz="-0.000000763  -0.000000289  0.053961822"/>
      <inertia ixx="0.000000000" ixy="0" ixz="0" iyy="0.000000000" iyz="0" izz="0.000000000"/>
    </inertial>
    <visual>
      <origin rpy="0  0  0" xyz="-0  -0  -0.1"/>
      <geometry>
        <mesh filename="package://plastun_description/meshes/STL_min/hokuyo.stl" scale="1 1 1"/>
      </geometry>
    </visual>
  </link>
  <!-- Turrel -->
  <link name="turrel_vniz">
    <inertial>
      <mass value="1"/>
      <origin rpy="0  0  0" xyz="0  0  0.072913938"/>
      <inertia ixx="0.166667" ixy="0" ixz="0" iyy="0.166667" iyz="0" izz="0.166667"/>
    </inertial>
    <collision>
      <origin rpy="0  0  0" xyz="0  0  0"/>
      <geometry>
        <mesh filename="package://plastun_description/meshes/STL_min/turrel_vniz.stl" scale="1.0 1.0 1.0"/>
      </geometry>
    </collision>
    <visual>
      <origin rpy="0  0  0" xyz="0  0  0"/>
      <geometry>
        <mesh filename="package://plastun_description/meshes/STL_min/turrel_vniz.stl" scale="1.0 1.0 1.0"/>
      </geometry>
      <material name="white"/>
    </visual>
  </link>
  <link name="turrel_sered">
    <inertial>
      <mass value="1"/>
      <origin rpy="0  0  0" xyz="0  -0.000000943  0.089683258"/>
      <inertia ixx="0.166667" ixy="0" ixz="0" iyy="0.166667" iyz="0" izz="0.166667"/>
    </inertial>
    <collision>
      <origin rpy="0  0  0" xyz="0  0  0"/>
      <geometry>
        <mesh filename="package://plastun_description/meshes/STL_min/turrel_sered.stl" scale="1.0 1.0 1.0"/>
      </geometry>
    </collision>
    <visual>
      <origin rpy="0  0  0" xyz="0  0  0"/>
      <geometry>
        <mesh filename="package://plastun_description/meshes/STL_min/turrel_sered.stl" scale="1.0 1.0 1.0"/>
      </geometry>
      <material name="brown"/>
    </visual>
  </link>
  <link name="turrel_vverh">
    <inertial>
      <mass value="1"/>
      <origin rpy="0  0  0" xyz="0    0   0.051670046"/>
      <inertia ixx="0.166667" ixy="0" ixz="0" iyy="0.166667" iyz="0" izz="0.166667"/>
    </inertial>
    <collision>
      <origin rpy="0  0  0" xyz="0    0   0"/>
      <geometry>
        <mesh filename="package://plastun_description/meshes/STL_min/turrel_vverh.stl" scale="1.0 1.0 1.0"/>
      </geometry>
    </collision>
    <visual>
      <origin rpy="0  0  0" xyz="0    0   0"/>
      <geometry>
        <mesh filename="package://plastun_description/meshes/STL_min/turrel_vverh.stl" scale="1.0 1.0 1.0"/>
      </geometry>
      <material name="blue"/>
    </visual>
  </link>
  <link name="camera_1">
    <inertial>
      <mass value="0.001"/>
      <origin rpy="0  0  0" xyz="0.000021536  -0.000000325  0.060192452"/>
      <inertia ixx="0.00034961" ixy="0" ixz="0" iyy="0.00243426" iyz="0" izz="0.0027544"/>
    </inertial>
    <collision>
      <origin rpy="0  0  0" xyz="-0.2  -0  -0.0546695"/>
      <geometry>
        <mesh filename="package://plastun_description/meshes/STL_min/camera.stl" scale="1 1 1"/>
      </geometry>
    </collision>
    <visual>
      <origin rpy="0  0  0" xyz="-0.2  -0  -0.0546695"/>
      <geometry>
        <mesh filename="package://plastun_description/meshes/STL_min/camera.stl" scale="1 1 1"/>
      </geometry>
    </visual>
  </link>
  <joint name="turrel_vverh_camera_1_fixed" type="fixed">
    <parent link="turrel_vverh"/>
    <child link="camera_1"/>
    <origin rpy="0       0       0" xyz="0.2  0.21 0.0576695"/>
    <axis xyz="0  0  0"/>
    <limit effort="0" lower="0" upper="0" velocity="0"/>
  </joint>
  <link name="camera_2">
    <inertial>
      <mass value="0.001"/>
      <origin rpy="0  0  0" xyz="0.000021536  -0.000000325  0.060192452"/>
      <inertia ixx="0.00034961" ixy="0" ixz="0" iyy="0.00243426" iyz="0" izz="0.0027544"/>
    </inertial>
    <collision>
      <origin rpy="0  0  0" xyz="-0.2  -0  -0.0546695"/>
      <geometry>
        <mesh filename="package://plastun_description/meshes/STL_min/camera.stl" scale="1 1 1"/>
      </geometry>
    </collision>
    <visual>
      <origin rpy="0  0  0" xyz="-0.2  -0  -0.0546695"/>
      <geometry>
        <mesh filename="package://plastun_description/meshes/STL_min/camera.stl" scale="1 1 1"/>
      </geometry>
    </visual>
  </link>
  <joint name="turrel_vverh_camera_2_fixed" type="fixed">
    <parent link="turrel_vverh"/>
    <child link="camera_2"/>
    <origin rpy="0       0       0" xyz="0.2  -0.21 0.0576695"/>
    <axis xyz="0  0  0"/>
    <limit effort="0" lower="0" upper="0" velocity="0"/>
  </joint>
  <link name="wheel_left_1">
    <inertial>
      <mass value="0.03"/>
      <origin rpy="0  0  0" xyz="0  0.000007723  0"/>
      <inertia ixx="0.000000000" ixy="0" ixz="0" iyy="0.000000000" iyz="0" izz="0.000000000"/>
    </inertial>
    <collision>
      <origin rpy="1.5708  0      0" xyz="0  0  0"/>
      <geometry>
        <cylinder length="0.09" radius="0.096"/>
      </geometry>
    </collision>
    <visual>
      <origin rpy="0  0  0" xyz="0  0  0"/>
      <geometry>
        <mesh filename="package://plastun_description/meshes/STL_min/wheel.stl" scale="1.0 1.0 1.0"/>
      </geometry>
    </visual>
  </link>
  <joint name="wheel_lev_1" type="revolute">
    <parent link="chassis"/>
    <child link="wheel_left_1"/>
    <origin rpy="0       0      0" xyz="0.0666644 0.20499   0.096"/>
    <axis xyz="0 1  0"/>
    <limit effort="-1" lower="-1e+100" upper="1e+100" velocity="100"/>
  </joint>
  <link name="wheel_left_2">
    <inertial>
      <mass value="0.03"/>
      <origin rpy="0  0  0" xyz="0  0.000007723  0"/>
      <inertia ixx="0.000000000" ixy="0" ixz="0" iyy="0.000000000" iyz="0" izz="0.000000000"/>
    </inertial>
    <visual>
      <origin rpy="0  0  0" xyz="0  0  0"/>
      <geometry>
        <mesh filename="package://plastun_description/meshes/STL_min/wheel.stl" scale="1.0 1.0 1.0"/>
      </geometry>
    </visual>
  </link>
  <joint name="wheel_lev_2" type="revolute">
    <parent link="chassis"/>
    <child link="wheel_left_2"/>
    <origin rpy="0       0      0" xyz="0.2881144 0.20499   0.096"/>
    <axis xyz="0 1  0"/>
    <limit effort="-1" lower="-1e+100" upper="1e+100" velocity="100"/>
  </joint>
  <link name="wheel_left_3">
    <inertial>
      <mass value="0.03"/>
      <origin rpy="0  0  0" xyz="0  0.000007723  0"/>
      <inertia ixx="0.000000000" ixy="0" ixz="0" iyy="0.000000000" iyz="0" izz="0.000000000"/>
    </inertial>
    <collision>
      <origin rpy="1.5708  0      0" xyz="0  0  0"/>
      <geometry>
        <cylinder length="0.09" radius="0.096"/>
      </geometry>
    </collision>
    <visual>
      <origin rpy="0  0  0" xyz="0  0  0"/>
      <geometry>
        <mesh filename="package://plastun_description/meshes/STL_min/wheel.stl" scale="1.0 1.0 1.0"/>
      </geometry>
    </visual>
  </link>
  <joint name="wheel_lev_3" type="revolute">
    <parent link="chassis"/>
    <child link="wheel_left_3"/>
    <origin rpy="0       0      0" xyz="0.5095644 0.20499   0.096"/>
    <axis xyz="0 1  0"/>
    <limit effort="-1" lower="-1e+100" upper="1e+100" velocity="100"/>
  </joint>
  <link name="wheel_right_1">
    <inertial>
      <mass value="0.03"/>
      <origin rpy="0  0  0" xyz="0  0.000007723  0"/>
      <inertia ixx="0.000000000" ixy="0" ixz="0" iyy="0.000000000" iyz="0" izz="0.000000000"/>
    </inertial>
    <collision>
      <origin rpy="1.5708  0      0" xyz="0  0  0"/>
      <geometry>
        <cylinder length="0.09" radius="0.096"/>
      </geometry>
    </collision>
    <visual>
      <origin rpy="0  0  0" xyz="0  0  0"/>
      <geometry>
        <mesh filename="package://plastun_description/meshes/STL_min/wheel.stl" scale="1.0 1.0 1.0"/>
      </geometry>
    </visual>
  </link>
  <joint name="wheel_prav_1" type="revolute">
    <parent link="chassis"/>
    <child link="wheel_right_1"/>
    <origin rpy="0       0      0" xyz="0.0666644 -0.20499   0.096"/>
    <axis xyz="0 1  0"/>
    <limit effort="-1" lower="-1e+100" upper="1e+100" velocity="100"/>
  </joint>
  <link name="wheel_right_2">
    <inertial>
      <mass value="0.03"/>
      <origin rpy="0  0  0" xyz="0  0.000007723  0"/>
      <inertia ixx="0.000000000" ixy="0" ixz="0" iyy="0.000000000" iyz="0" izz="0.000000000"/>
    </inertial>
    <visual>
      <origin rpy="0  0  0" xyz="0  0  0"/>
      <geometry>
        <mesh filename="package://plastun_description/meshes/STL_min/wheel.stl" scale="1.0 1.0 1.0"/>
      </geometry>
    </visual>
  </link>
  <joint name="wheel_prav_2" type="revolute">
    <parent link="chassis"/>
    <child link="wheel_right_2"/>
    <origin rpy="0       0      0" xyz="0.2881144 -0.20499   0.096"/>
    <axis xyz="0 1  0"/>
    <limit effort="-1" lower="-1e+100" upper="1e+100" velocity="100"/>
  </joint>
  <link name="wheel_right_3">
    <inertial>
      <mass value="0.03"/>
      <origin rpy="0  0  0" xyz="0  0.000007723  0"/>
      <inertia ixx="0.000000000" ixy="0" ixz="0" iyy="0.000000000" iyz="0" izz="0.000000000"/>
    </inertial>
    <collision>
      <origin rpy="1.5708  0      0" xyz="0  0  0"/>
      <geometry>
        <cylinder length="0.09" radius="0.096"/>
      </geometry>
    </collision>
    <visual>
      <origin rpy="0  0  0" xyz="0  0  0"/>
      <geometry>
        <mesh filename="package://plastun_description/meshes/STL_min/wheel.stl" scale="1.0 1.0 1.0"/>
      </geometry>
    </visual>
  </link>
  <joint name="wheel_prav_3" type="revolute">
    <parent link="chassis"/>
    <child link="wheel_right_3"/>
    <origin rpy="0       0      0" xyz="0.5095644 -0.20499   0.096"/>
    <axis xyz="0 1  0"/>
    <limit effort="-1" lower="-1e+100" upper="1e+100" velocity="100"/>
  </joint>
  <!--fix'es joints -->
  <joint name="camera_1_lazer_ukazka_fixed" type="fixed">
    <parent link="camera_1"/>
    <child link="lazer_ukazka"/>
    <origin rpy="0       0      0" xyz="0.071  0  0.095"/>
    <axis xyz="0  0  0"/>
    <limit effort="0" lower="0" upper="0" velocity="0"/>
  </joint>
  <joint name="chassis_hokuyo_fixed" type="fixed">
    <parent link="chassis"/>
    <child link="hokuyo"/>
    <origin rpy="0       0       0" xyz="0.4941421  -0.083  0.4685"/>
    <axis xyz="0  0  0"/>
    <limit effort="0" lower="0" upper="0" velocity="0"/>
  </joint>
  <joint name="chassis_turrel_vniz_fixed" type="fixed">
    <parent link="chassis"/>
    <child link="turrel_vniz"/>
    <origin rpy="0 0  0" xyz="0.395 0  0.3685"/>
    <axis xyz="0  0  0"/>
    <limit effort="0" lower="0" upper="0" velocity="0"/>
  </joint>
  <!-- revolute joints -->
  <joint name="turrel_vniz_turrel_sered_revolute" type="revolute">
    <parent link="turrel_vniz"/>
    <child link="turrel_sered"/>
    <origin rpy="0  0   0" xyz="0 0  0.1296088"/>
    <axis xyz="0  0  1"/>
    <limit effort="1" lower="-3.139" upper="3.139" velocity="100"/>
  </joint>
  <joint name="turrel_sered_turrel_vverh_up_to_down" type="revolute">
    <parent link="turrel_sered"/>
    <child link="turrel_vverh"/>
    <origin rpy="0   0   0" xyz="0  0 0.0890008"/>
    <axis xyz="0  -1  0"/>
    <limit effort="1" lower="-1" upper="1" velocity="100"/>
  </joint>
  <!--transmitions-->
  <transmission name="turrel_revol">
    <type>transmission_interface/SimpleTransmission</type>
    <joint name="turrel_vniz_turrel_sered_revolute">
      <hardwareInterface>EffortJointInterface</hardwareInterface>
    </joint>
    <actuator name="tl_rev">
      <hardwareInterface>EffortJointInterface</hardwareInterface>
      <mechanicalReduction>1</mechanicalReduction>
    </actuator>
  </transmission>
  <transmission name="turrel_up_to_down">
    <type>transmission_interface/SimpleTransmission</type>
    <joint name="turrel_sered_turrel_vverh_up_to_down">
      <hardwareInterface>EffortJointInterface</hardwareInterface>
    </joint>
    <actuator name="tl_ud">
      <hardwareInterface>EffortJointInterface</hardwareInterface>
      <mechanicalReduction>1</mechanicalReduction>
    </actuator>
  </transmission>
  <transmission name="wheel_l_1">
    <type>transmission_interface/SimpleTransmission</type>
    <joint name="wheel_lev_1">
      <hardwareInterface>EffortJointInterface</hardwareInterface>
    </joint>
    <actuator name="wh_l_1">
      <hardwareInterface>EffortJointInterface</hardwareInterface>
      <mechanicalReduction>1</mechanicalReduction>
    </actuator>
  </transmission>
  <transmission name="wheel_l_2">
    <type>transmission_interface/SimpleTransmission</type>
    <joint name="wheel_lev_2">
      <hardwareInterface>EffortJointInterface</hardwareInterface>
    </joint>
    <actuator name="wh_l_2">
      <hardwareInterface>EffortJointInterface</hardwareInterface>
      <mechanicalReduction>1</mechanicalReduction>
    </actuator>
  </transmission>
  <transmission name="wheel_l_3">
    <type>transmission_interface/SimpleTransmission</type>
    <joint name="wheel_lev_3">
      <hardwareInterface>EffortJointInterface</hardwareInterface>
    </joint>
    <actuator name="wh_l_3">
      <hardwareInterface>EffortJointInterface</hardwareInterface>
      <mechanicalReduction>1</mechanicalReduction>
    </actuator>
  </transmission>
  <transmission name="wheel_r_1">
    <type>transmission_interface/SimpleTransmission</type>
    <joint name="wheel_prav_1">
      <hardwareInterface>EffortJointInterface</hardwareInterface>
    </joint>
    <actuator name="wh_r_1">
      <hardwareInterface>EffortJointInterface</hardwareInterface>
      <mechanicalReduction>1</mechanicalReduction>
    </actuator>
  </transmission>
  <transmission name="wheel_r_2">
    <type>transmission_interface/SimpleTransmission</type>
    <joint name="wheel_prav_2">
      <hardwareInterface>EffortJointInterface</hardwareInterface>
    </joint>
    <actuator name="wh_r_2">
      <hardwareInterface>EffortJointInterface</hardwareInterface>
      <mechanicalReduction>1</mechanicalReduction>
    </actuator>
  </transmission>
  <transmission name="wheel_r_3">
    <type>transmission_interface/SimpleTransmission</type>
    <joint name="wheel_prav_3">
      <hardwareInterface>EffortJointInterface</hardwareInterface>
    </joint>
    <actuator name="wh_r_3">
      <hardwareInterface>EffortJointInterface</hardwareInterface>
      <mechanicalReduction>1</mechanicalReduction>
    </actuator>
  </transmission>
</robot>

