<?xml version="1.0" ?>
<!-- =================================================================================== -->
<!-- |    This document was autogenerated by xacro from plastun.xacro                  | -->
<!-- |    EDITING THIS FILE BY HAND IS NOT RECOMMENDED                                 | -->
<!-- =================================================================================== -->
<robot name="MRC_Plastun" xmlns:xacro="http://www.ros.org/wiki/xacro">
  <!-- plugins -->
  <gazebo>
    <plugin filename="libgazebo_ros_control.so" name="gazebo_ros_control">
      <robotNamespace>plastun</robotNamespace>
    </plugin>
  </gazebo>
  <gazebo>
    <plugin filename="libgazebo_ros_skid_steer_drive.so" name="skid_steer_drive_controller">
      <updateRate>100.0</updateRate>
      <robotNamespace>plastun</robotNamespace>
      <leftFrontJoint>wheel_lev_1</leftFrontJoint>
      <rightFrontJoint>wheel_prav_1</rightFrontJoint>
      <leftRearJoint>wheel_lev_3</leftRearJoint>
      <rightRearJoint>wheel_prav_3</rightRearJoint>
      <wheelSeparation>0.4</wheelSeparation>
      <wheelDiameter>0.192</wheelDiameter>
      <robotBaseFrame>chassis</robotBaseFrame>
      <torque>20</torque>
      <commandTopic>cmd_vel</commandTopic>
      <odometryTopic>odom</odometryTopic>
      <odometryFrame>odom</odometryFrame>
      <broadcastTF>true</broadcastTF>
      <covariance_x>0.000100</covariance_x>
      <covariance_y>0.000100</covariance_y>
      <covariance_yaw>0.000100</covariance_yaw>
    </plugin>
  </gazebo>
  <!-- sensors -->
  <gazebo reference="camera_1">
    <sensor name="camera_with_laser" type="camera">
      <pose>-0.14 0 0.06 0 0.000000 3.1416</pose>
      <camera name="__default__">
        <horizontal_fov>1.012300</horizontal_fov>
        <image>
          <width>320</width>
          <height>200</height>
        </image>
        <clip>
          <near>0.001000</near>
          <far>100.000000</far>
        </clip>
      </camera>
      <always_on>1</always_on>
      <update_rate>30.000000</update_rate>
      <visualize>true</visualize>
      <plugin filename="libgazebo_ros_camera.so" name="camera_with_laser_controller">
        <alwaysOn>true</alwaysOn>
        <updateRate>30</updateRate>
        <cameraName>camera_1</cameraName>
        <robotNamespace>plastun</robotNamespace>
        <imageTopicName>image_raw_1</imageTopicName>
        <cameraInfoTopicName>camera_info_1</cameraInfoTopicName>
        <frameName>camera_1</frameName>
        <hackBaseline>0.07</hackBaseline>
        <distortionK1>0.0</distortionK1>
        <distortionK2>0.0</distortionK2>
        <distortionK3>0.0</distortionK3>
        <distortionT1>0.0</distortionT1>
        <distortionT2>0.0</distortionT2>
      </plugin>
    </sensor>
  </gazebo>
  <gazebo reference="camera_2">
    <sensor name="camera_without_laser" type="camera">
      <pose>-0.14 0 0.06 0 0.000000 3.1416</pose>
      <camera name="__default__">
        <horizontal_fov>1.012300</horizontal_fov>
        <image>
          <width>320</width>
          <height>200</height>
        </image>
        <clip>
          <near>0.001000</near>
          <far>100.000000</far>
        </clip>
      </camera>
      <always_on>1</always_on>
      <update_rate>30.000000</update_rate>
      <visualize>false</visualize>
      <plugin filename="libgazebo_ros_camera.so" name="camera_without_laser_controller">
        <alwaysOn>true</alwaysOn>
        <updateRate>30</updateRate>
        <cameraName>camera_2</cameraName>
        <imageTopicName>image_raw_2</imageTopicName>
        <robotNamespace>plastun</robotNamespace>
        <cameraInfoTopicName>camera_info_2</cameraInfoTopicName>
        <frameName>camera_2</frameName>
        <hackBaseline>0.07</hackBaseline>
        <distortionK1>0.0</distortionK1>
        <distortionK2>0.0</distortionK2>
        <distortionK3>0.0</distortionK3>
        <distortionT1>0.0</distortionT1>
        <distortionT2>0.0</distortionT2>
      </plugin>
    </sensor>
  </gazebo>
  <gazebo reference="hokuyo">
    <sensor name="hokuyo_sensor" type="gpu_ray">
      <pose>0 0 0.1 0 0 3.1416</pose>
      <visualize>true</visualize>
      <update_rate>40</update_rate>
      <ray>
        <scan>
          <horizontal>
            <samples>720</samples>
            <resolution>1</resolution>
            <min_angle>-1.470796</min_angle>
            <max_angle>1.470796</max_angle>
          </horizontal>
        </scan>
        <range>
          <min>0.10</min>
          <max>15.0</max>
          <resolution>0.01</resolution>
        </range>
        <noise>
          <type>gaussian</type>
          <mean>0.0</mean>
          <stddev>0.01</stddev>
        </noise>
      </ray>
      <plugin filename="libgazebo_ros_gpu_laser.so" name="gazebo_ros_hokuyo_sensor">
        <robotNamespace>plastun</robotNamespace>
        <topicName>laser/scan</topicName>
        <frameName>hokuyo</frameName>
      </plugin>
    </sensor>
  </gazebo>
  <gazebo reference="lazer_ukazka">
    <sensor name="hokuyo_laser_ukaz" type="gpu_ray">
      <pose>-0.1 0 0.05 0 0 3.1416</pose>
      <visualize>true</visualize>
      <update_rate>40</update_rate>
      <ray>
        <scan>
          <horizontal>
            <samples>6</samples>
            <resolution>1</resolution>
            <min_angle>-0.005</min_angle>
            <max_angle>0.005</max_angle>
          </horizontal>
        </scan>
        <range>
          <min>0.10</min>
          <max>10.0</max>
          <resolution>0.01</resolution>
        </range>
        <noise>
          <type>gaussian</type>
          <mean>0.0</mean>
          <stddev>0.01</stddev>
        </noise>
      </ray>
      <plugin filename="libgazebo_ros_gpu_laser.so" name="gazebo_ros_hokuyo_laser_ukaz">
        <robotNamespace>plastun</robotNamespace>
        <topicName>laser/scan_ukaz</topicName>
        <frameName>ukaz</frameName>
      </plugin>
    </sensor>
  </gazebo>
  <!--Import Gazebo colors -->
  <gazebo reference="chassis">
    <material>Gazebo/Grey</material>
  </gazebo>
  <gazebo reference="turrel_vniz">
    <material>Gazebo/Grey</material>
  </gazebo>
  <gazebo reference="turrel_sered">
    <material>Gazebo/Grey</material>
  </gazebo>
  <gazebo reference="turrel_vverh">
    <material>Gazebo/Grey</material>
  </gazebo>
  <gazebo reference="hokuyo">
    <material>Gazebo/Grey</material>
  </gazebo>
  <gazebo reference="camera_1">
    <material>Gazebo/Grey</material>
  </gazebo>
  <gazebo reference="camera_2">
    <material>Gazebo/Grey</material>
  </gazebo>
  <material name="black">
    <color rgba="0.0 0.0 0.0 1.0"/>
  </material>
  <material name="blue">
    <color rgba="0.0 0.0 0.8 1.0"/>
  </material>
  <material name="green">
    <color rgba="0.0 0.8 0.0 1.0"/>
  </material>
  <material name="grey">
    <color rgba="0.2 0.2 0.2 1.0"/>
  </material>
  <material name="orange">
    <color rgba="1.0 0.423529411765 0.0392156862745 1.0"/>
  </material>
  <material name="brown">
    <color rgba="0.870588235294 0.811764705882 0.764705882353 1.0"/>
  </material>
  <material name="red">
    <color rgba="0.8 0.0 0.0 1.0"/>
  </material>
  <material name="white">
    <color rgba="1.0 1.0 1.0 1.0"/>
  </material>
  <link name="base_link"/>
  <joint name="chassis_base_link_fixed" type="fixed">
    <parent link="base_link"/>
    <child link="chassis"/>
  </joint>
  <link name="chassis">
    <inertial>
      <mass value="30"/>
      <origin rpy="0  0  0" xyz="0.436419 -0.000612  0.228789"/>
      <inertia ixx="0.166667" ixy="0" ixz="0" iyy="0.166667" iyz="0" izz="0.166667"/>
    </inertial>
    <collision>
      <origin rpy="0  0  0" xyz="0 0  0"/>
      <geometry>
        <mesh filename="package://plastun_description/meshes/STL_min/chassis.stl" scale="1.0 1.0 1.0"/>
      </geometry>
    </collision>
    <visual>
      <origin rpy="0  0  0" xyz="0 0  0"/>
      <geometry>
        <mesh filename="package://plastun_description/meshes/STL_min/chassis.stl" scale="1 1 1"/>
      </geometry>
      <material name="green"/>
    </visual>
  </link>
  <!--laser sensors -->
  <link name="lazer_ukazka">
    <inertial>
      <mass value="0.001"/>
      <origin rpy="0  0  0" xyz="-0.017806  0  0.027446"/>
      <inertia ixx="0.0" ixy="0" ixz="0" iyy="0.0" iyz="0" izz="0.0"/>
    </inertial>
    <collision>
      <origin rpy="0  0  0" xyz="0  0  0"/>
      <geometry>
        <mesh filename="package://plastun_description/meshes/STL_min/lazer_ukazka.stl" scale="1.0 1.0 1.0"/>
      </geometry>
    </collision>
    <visual>
      <origin rpy="0  0  0" xyz="0  0  0"/>
      <geometry>
        <mesh filename="package://plastun_description/meshes/STL_min/lazer_ukazka.stl" scale="1.0 1.0 1.0"/>
      </geometry>
      <material name="white"/>
    </visual>
  </link>
  <link name="hokuyo">
    <inertial>
      <mass value="0.3"/>
      <origin rpy="0  0  0" xyz="-0.000001  0  0.053927"/>
      <inertia ixx="0.166667" ixy="0" ixz="0" iyy="0.166667" iyz="0" izz="0.166667"/>
    </inertial>
    <collision>
      <origin rpy="0  0  0" xyz="0    0    0.05"/>
      <geometry>
        <box size="0.06524 0.079833 0.102579"/>
      </geometry>
    </collision>
    <visual>
      <origin rpy="0  0  0" xyz="0  0  0"/>
      <geometry>
        <mesh filename="package://plastun_description/meshes/STL_min/hokuyo.stl" scale="1 1 1"/>
      </geometry>
    </visual>
  </link>
  <!-- Turrel -->
  <link name="turrel_vniz">
    <inertial>
      <mass value="1"/>
      <origin rpy="0  0  0" xyz="-0.000002  0  0.072908"/>
      <inertia ixx="0.166667" ixy="0" ixz="0" iyy="0.166667" iyz="0" izz="0.166667"/>
    </inertial>
    <collision>
      <origin rpy="0  0  0" xyz="0  0  0"/>
      <geometry>
        <mesh filename="package://plastun_description/meshes/STL_min/turrel_vniz.stl" scale="1.0 1.0 1.0"/>
      </geometry>
    </collision>
    <visual>
      <origin rpy="0  0  0" xyz="0  0  0"/>
      <geometry>
        <mesh filename="package://plastun_description/meshes/STL_min/turrel_vniz.stl" scale="1.0 1.0 1.0"/>
      </geometry>
      <material name="white"/>
    </visual>
  </link>
  <link name="turrel_sered">
    <inertial>
      <mass value="1"/>
      <origin rpy="0  0  0" xyz="0  0  0.089664"/>
      <inertia ixx="0.166667" ixy="0" ixz="0" iyy="0.166667" iyz="0" izz="0.166667"/>
    </inertial>
    <collision>
      <origin rpy="0  0  0" xyz="0  0  0"/>
      <geometry>
        <mesh filename="package://plastun_description/meshes/STL_min/turrel_sered.stl" scale="1.0 1.0 1.0"/>
      </geometry>
    </collision>
    <visual>
      <origin rpy="0  0  0" xyz="0  0  0"/>
      <geometry>
        <mesh filename="package://plastun_description/meshes/STL_min/turrel_sered.stl" scale="1.0 1.0 1.0"/>
      </geometry>
      <material name="brown"/>
    </visual>
  </link>
  <link name="turrel_vverh">
    <inertial>
      <mass value="1"/>
      <origin rpy="0  0  0" xyz="0    -0.005000   0.051671"/>
      <inertia ixx="0.166667" ixy="0" ixz="0" iyy="0.166667" iyz="0" izz="0.166667"/>
    </inertial>
    <collision>
      <origin rpy="0  0  0" xyz="0    0   0"/>
      <geometry>
        <mesh filename="package://plastun_description/meshes/STL_min/turrel_vverh.stl" scale="1.0 1.0 1.0"/>
      </geometry>
    </collision>
    <visual>
      <origin rpy="0  0  0" xyz="0    0   0"/>
      <geometry>
        <mesh filename="package://plastun_description/meshes/STL_min/turrel_vverh.stl" scale="1.0 1.0 1.0"/>
      </geometry>
      <material name="blue"/>
    </visual>
  </link>
  <link name="camera_1">
    <inertial>
      <mass value="0.001"/>
      <origin rpy="0  0  0" xyz="-0.000018  -0.000225  0.060158"/>
      <inertia ixx="0.00034961" ixy="0" ixz="0" iyy="0.00243426" iyz="0" izz="0.0027544"/>
    </inertial>
    <collision>
      <origin rpy="0  0  0" xyz="0  0  0"/>
      <geometry>
        <mesh filename="package://plastun_description/meshes/STL_min/camera.stl" scale="1 1 1"/>
      </geometry>
    </collision>
    <visual>
      <origin rpy="0  0  0" xyz="0  0  0"/>
      <geometry>
        <mesh filename="package://plastun_description/meshes/STL_min/camera.stl" scale="1 1 1"/>
      </geometry>
    </visual>
  </link>
  <joint name="turrel_vverh_camera_1_fixed" type="revolute">
    <parent link="turrel_vverh"/>
    <child link="camera_1"/>
    <origin rpy="0       0       0" xyz="-0.07152  -0.21176 0"/>
    <axis xyz="0  0  1"/>
    <limit effort="0" lower="0" upper="0" velocity="0"/>
  </joint>
  <link name="camera_2">
    <inertial>
      <mass value="0.001"/>
      <origin rpy="0  0  0" xyz="-0.000018  -0.000225  0.060158"/>
      <inertia ixx="0.00034961" ixy="0" ixz="0" iyy="0.00243426" iyz="0" izz="0.0027544"/>
    </inertial>
    <collision>
      <origin rpy="0  0  0" xyz="0  0  0"/>
      <geometry>
        <mesh filename="package://plastun_description/meshes/STL_min/camera.stl" scale="1 1 1"/>
      </geometry>
    </collision>
    <visual>
      <origin rpy="0  0  0" xyz="0  0  0"/>
      <geometry>
        <mesh filename="package://plastun_description/meshes/STL_min/camera.stl" scale="1 1 1"/>
      </geometry>
    </visual>
  </link>
  <joint name="turrel_vverh_camera_2_fixed" type="revolute">
    <parent link="turrel_vverh"/>
    <child link="camera_2"/>
    <origin rpy="0       0       0" xyz="-0.07152  0.21176 0"/>
    <axis xyz="0  0  1"/>
    <limit effort="0" lower="0" upper="0" velocity="0"/>
  </joint>
  <link name="wheel_left_1">
    <inertial>
      <mass value="1"/>
      <origin rpy="0  0  0" xyz="0  0.000008  0"/>
      <inertia ixx="0.166667" ixy="0" ixz="0" iyy="0.166667" iyz="0" izz="0.166667"/>
    </inertial>
    <collision>
      <origin rpy="1.5708  0      0" xyz="0  0  0"/>
      <geometry>
        <cylinder length="0.09" radius="0.096"/>
      </geometry>
    </collision>
    <visual>
      <origin rpy="0  0  0" xyz="0  0  0"/>
      <geometry>
        <mesh filename="package://plastun_description/meshes/STL_min/wheel.stl" scale="1.0 1.0 1.0"/>
      </geometry>
    </visual>
  </link>
  <joint name="wheel_lev_1" type="revolute">
    <parent link="chassis"/>
    <child link="wheel_left_1"/>
    <origin rpy="0       0      0" xyz="0.1405513 -0.20499   0.0925"/>
    <axis xyz="0 -1  0"/>
    <limit effort="-1" lower="-1e+50" upper="1e+50" velocity="100"/>
  </joint>
  <link name="wheel_left_2">
    <inertial>
      <mass value="1"/>
      <origin rpy="0  0  0" xyz="0  0.000008  0"/>
      <inertia ixx="0.166667" ixy="0" ixz="0" iyy="0.166667" iyz="0" izz="0.166667"/>
    </inertial>
    <collision>
      <origin rpy="1.5708  0      0" xyz="0  0  0"/>
      <geometry>
        <cylinder length="0.09" radius="0.096"/>
      </geometry>
    </collision>
    <visual>
      <origin rpy="0  0  0" xyz="0  0  0"/>
      <geometry>
        <mesh filename="package://plastun_description/meshes/STL_min/wheel.stl" scale="1.0 1.0 1.0"/>
      </geometry>
    </visual>
  </link>
  <joint name="wheel_lev_2" type="revolute">
    <parent link="chassis"/>
    <child link="wheel_left_2"/>
    <origin rpy="0       0      0" xyz="0.3618856 -0.20499   0.0925"/>
    <axis xyz="0 -1  0"/>
    <limit effort="-1" lower="-1e+50" upper="1e+50" velocity="100"/>
  </joint>
  <link name="wheel_left_3">
    <inertial>
      <mass value="1"/>
      <origin rpy="0  0  0" xyz="0  0.000008  0"/>
      <inertia ixx="0.166667" ixy="0" ixz="0" iyy="0.166667" iyz="0" izz="0.166667"/>
    </inertial>
    <collision>
      <origin rpy="1.5708  0      0" xyz="0  0  0"/>
      <geometry>
        <cylinder length="0.09" radius="0.096"/>
      </geometry>
    </collision>
    <visual>
      <origin rpy="0  0  0" xyz="0  0  0"/>
      <geometry>
        <mesh filename="package://plastun_description/meshes/STL_min/wheel.stl" scale="1.0 1.0 1.0"/>
      </geometry>
    </visual>
  </link>
  <joint name="wheel_lev_3" type="revolute">
    <parent link="chassis"/>
    <child link="wheel_left_3"/>
    <origin rpy="0       0      0" xyz="0.5832199 -0.20499   0.0925"/>
    <axis xyz="0 -1  0"/>
    <limit effort="-1" lower="-1e+50" upper="1e+50" velocity="100"/>
  </joint>
  <link name="wheel_right_1">
    <inertial>
      <mass value="1"/>
      <origin rpy="0  0  0" xyz="0  0.000008  0"/>
      <inertia ixx="0.166667" ixy="0" ixz="0" iyy="0.166667" iyz="0" izz="0.166667"/>
    </inertial>
    <collision>
      <origin rpy="1.5708  0      0" xyz="0  0  0"/>
      <geometry>
        <cylinder length="0.09" radius="0.096"/>
      </geometry>
    </collision>
    <visual>
      <origin rpy="0  0  0" xyz="0  0  0"/>
      <geometry>
        <mesh filename="package://plastun_description/meshes/STL_min/wheel.stl" scale="1.0 1.0 1.0"/>
      </geometry>
    </visual>
  </link>
  <joint name="wheel_prav_1" type="revolute">
    <parent link="chassis"/>
    <child link="wheel_right_1"/>
    <origin rpy="0       0      0" xyz="0.1405513 0.20499   0.0925"/>
    <axis xyz="0 -1  0"/>
    <limit effort="-1" lower="-1e+50" upper="1e+50" velocity="100"/>
  </joint>
  <link name="wheel_right_2">
    <inertial>
      <mass value="1"/>
      <origin rpy="0  0  0" xyz="0  0.000008  0"/>
      <inertia ixx="0.166667" ixy="0" ixz="0" iyy="0.166667" iyz="0" izz="0.166667"/>
    </inertial>
    <collision>
      <origin rpy="1.5708  0      0" xyz="0  0  0"/>
      <geometry>
        <cylinder length="0.09" radius="0.096"/>
      </geometry>
    </collision>
    <visual>
      <origin rpy="0  0  0" xyz="0  0  0"/>
      <geometry>
        <mesh filename="package://plastun_description/meshes/STL_min/wheel.stl" scale="1.0 1.0 1.0"/>
      </geometry>
    </visual>
  </link>
  <joint name="wheel_prav_2" type="revolute">
    <parent link="chassis"/>
    <child link="wheel_right_2"/>
    <origin rpy="0       0      0" xyz="0.3618856 0.20499   0.0925"/>
    <axis xyz="0 -1  0"/>
    <limit effort="-1" lower="-1e+50" upper="1e+50" velocity="100"/>
  </joint>
  <link name="wheel_right_3">
    <inertial>
      <mass value="1"/>
      <origin rpy="0  0  0" xyz="0  0.000008  0"/>
      <inertia ixx="0.166667" ixy="0" ixz="0" iyy="0.166667" iyz="0" izz="0.166667"/>
    </inertial>
    <collision>
      <origin rpy="1.5708  0      0" xyz="0  0  0"/>
      <geometry>
        <cylinder length="0.09" radius="0.096"/>
      </geometry>
    </collision>
    <visual>
      <origin rpy="0  0  0" xyz="0  0  0"/>
      <geometry>
        <mesh filename="package://plastun_description/meshes/STL_min/wheel.stl" scale="1.0 1.0 1.0"/>
      </geometry>
    </visual>
  </link>
  <joint name="wheel_prav_3" type="revolute">
    <parent link="chassis"/>
    <child link="wheel_right_3"/>
    <origin rpy="0       0      0" xyz="0.5832199 0.20499   0.0925"/>
    <axis xyz="0 -1  0"/>
    <limit effort="-1" lower="-1e+50" upper="1e+50" velocity="100"/>
  </joint>
  <!--fix'es joints -->
  <joint name="camera_1_lazer_ukazka_fixed" type="revolute">
    <parent link="camera_1"/>
    <child link="lazer_ukazka"/>
    <origin rpy="0       0      0" xyz="-0.04766  0.00111  0.10548"/>
    <axis xyz="0  0  1"/>
    <limit effort="0" lower="0" upper="0" velocity="0"/>
  </joint>
  <joint name="chassis_hokuyo_fixed" type="revolute">
    <parent link="chassis"/>
    <child link="hokuyo"/>
    <origin rpy="0       0       0" xyz="0.14586  0.083   0.365"/>
    <axis xyz="0  0  1"/>
    <limit effort="0" lower="0" upper="0" velocity="0"/>
  </joint>
  <joint name="chassis_turrel_vniz_fixed" type="fixed">
    <parent link="chassis"/>
    <child link="turrel_vniz"/>
    <origin rpy="0 0  0" xyz="0.255 0  0.37358"/>
    <axis xyz="0  0  0"/>
    <limit effort="0" lower="0" upper="0" velocity="0"/>
  </joint>
  <!-- revolute joints -->
  <joint name="turrel_vniz_turrel_sered_revolute" type="revolute">
    <parent link="turrel_vniz"/>
    <child link="turrel_sered"/>
    <origin rpy="0  0   0" xyz="0 0  0.13474"/>
    <axis xyz="0  0  1"/>
    <limit effort="1" lower="-7" upper="7" velocity="10"/>
  </joint>
  <joint name="turrel_sered_turrel_vverh_up_to_down" type="revolute">
    <parent link="turrel_sered"/>
    <child link="turrel_vverh"/>
    <origin rpy="0   0   0" xyz="0  0.005 0.1"/>
    <axis xyz="0  1  0"/>
    <limit effort="1" lower="-1" upper="1" velocity="100"/>
  </joint>
  <!--transmitions-->
  <transmission name="turrel_revol">
    <type>transmission_interface/SimpleTransmission</type>
    <joint name="turrel_vniz_turrel_sered_revolute">
      <hardwareInterface>EffortJointInterface</hardwareInterface>
    </joint>
    <actuator name="tl_rev">
      <hardwareInterface>EffortJointInterface</hardwareInterface>
      <mechanicalReduction>1</mechanicalReduction>
    </actuator>
  </transmission>
  <transmission name="turrel_up_to_down">
    <type>transmission_interface/SimpleTransmission</type>
    <joint name="turrel_sered_turrel_vverh_up_to_down">
      <hardwareInterface>EffortJointInterface</hardwareInterface>
    </joint>
    <actuator name="tl_ud">
      <hardwareInterface>EffortJointInterface</hardwareInterface>
      <mechanicalReduction>1</mechanicalReduction>
    </actuator>
  </transmission>
  <transmission name="chassis_hokuyo_fix">
    <type>transmission_interface/SimpleTransmission</type>
    <joint name="chassis_hokuyo_fixed">
      <hardwareInterface>EffortJointInterface</hardwareInterface>
    </joint>
    <actuator name="chas_hok_fix">
      <hardwareInterface>EffortJointInterface</hardwareInterface>
      <mechanicalReduction>1</mechanicalReduction>
    </actuator>
  </transmission>
  <transmission name="wheel_l_1">
    <type>transmission_interface/SimpleTransmission</type>
    <joint name="wheel_lev_1">
      <hardwareInterface>EffortJointInterface</hardwareInterface>
    </joint>
    <actuator name="wh_l_1">
      <hardwareInterface>EffortJointInterface</hardwareInterface>
      <mechanicalReduction>1</mechanicalReduction>
    </actuator>
  </transmission>
  <transmission name="wheel_l_2">
    <type>transmission_interface/SimpleTransmission</type>
    <joint name="wheel_lev_2">
      <hardwareInterface>EffortJointInterface</hardwareInterface>
    </joint>
    <actuator name="wh_l_2">
      <hardwareInterface>EffortJointInterface</hardwareInterface>
      <mechanicalReduction>1</mechanicalReduction>
    </actuator>
  </transmission>
  <transmission name="wheel_l_3">
    <type>transmission_interface/SimpleTransmission</type>
    <joint name="wheel_lev_3">
      <hardwareInterface>EffortJointInterface</hardwareInterface>
    </joint>
    <actuator name="wh_l_3">
      <hardwareInterface>EffortJointInterface</hardwareInterface>
      <mechanicalReduction>1</mechanicalReduction>
    </actuator>
  </transmission>
  <transmission name="wheel_r_1">
    <type>transmission_interface/SimpleTransmission</type>
    <joint name="wheel_prav_1">
      <hardwareInterface>EffortJointInterface</hardwareInterface>
    </joint>
    <actuator name="wh_r_1">
      <hardwareInterface>EffortJointInterface</hardwareInterface>
      <mechanicalReduction>1</mechanicalReduction>
    </actuator>
  </transmission>
  <transmission name="wheel_r_2">
    <type>transmission_interface/SimpleTransmission</type>
    <joint name="wheel_prav_2">
      <hardwareInterface>EffortJointInterface</hardwareInterface>
    </joint>
    <actuator name="wh_r_2">
      <hardwareInterface>EffortJointInterface</hardwareInterface>
      <mechanicalReduction>1</mechanicalReduction>
    </actuator>
  </transmission>
  <transmission name="wheel_r_3">
    <type>transmission_interface/SimpleTransmission</type>
    <joint name="wheel_prav_3">
      <hardwareInterface>EffortJointInterface</hardwareInterface>
    </joint>
    <actuator name="wh_r_3">
      <hardwareInterface>EffortJointInterface</hardwareInterface>
      <mechanicalReduction>1</mechanicalReduction>
    </actuator>
  </transmission>
  <transmission name="camer_1">
    <type>transmission_interface/SimpleTransmission</type>
    <joint name="turrel_vverh_camera_1_fixed">
      <hardwareInterface>EffortJointInterface</hardwareInterface>
    </joint>
    <actuator name="cam_1">
      <hardwareInterface>EffortJointInterface</hardwareInterface>
      <mechanicalReduction>1</mechanicalReduction>
    </actuator>
  </transmission>
  <transmission name="camer_2">
    <type>transmission_interface/SimpleTransmission</type>
    <joint name="turrel_vverh_camera_2_fixed">
      <hardwareInterface>EffortJointInterface</hardwareInterface>
    </joint>
    <actuator name="cam_2">
      <hardwareInterface>EffortJointInterface</hardwareInterface>
      <mechanicalReduction>1</mechanicalReduction>
    </actuator>
  </transmission>
  <transmission name="camera_1_ukaz_fix">
    <type>transmission_interface/SimpleTransmission</type>
    <joint name="camera_1_lazer_ukazka_fixed">
      <hardwareInterface>EffortJointInterface</hardwareInterface>
    </joint>
    <actuator name="cam_uk_fix">
      <hardwareInterface>EffortJointInterface</hardwareInterface>
      <mechanicalReduction>1</mechanicalReduction>
    </actuator>
  </transmission>
</robot>

